Workbook
Name Holidays: Setting!$B:$C
Name Week1: #REF!

Sheet Leave Master Sheet Blank
I2: Monthly Leave Tracker
F3: January | G3: 2023 | H3: =IFERROR(VLOOKUP(H4,Holidays,2,0),"") | I3: =IFERROR(VLOOKUP(I4,Holidays,2,0),"") | J3: =IFERROR(VLOOKUP(J4,Holidays,2,0),"") | K3: =IFERROR(VLOOKUP(K4,Holidays,2,0),"") | L3: =IFERROR(VLOOKUP(L4,Holidays,2,0),"") | M3: =IFERROR(VLOOKUP(M4,Holidays,2,0),"") | N3: =IFERROR(VLOOKUP(N4,Holidays,2,0),"") | O3: =IFERROR(VLOOKUP(O4,Holidays,2,0),"") | ... AL3: =IFERROR(VLOOKUP(AL4,Holidays,2,0),"") | AM3: Summary
D4: SL. No. | E4: Emp. Code | F4: Name | G4: Designation | H4: =DATEVALUE("1"&F3&G3) -> 44927 | I4: =IF(H$4<EOMONTH($H$4,0),H4+1,"EOM") -> 44928 | J4: =IF(I$4<EOMONTH($H$4,0),I4+1,"EOM") -> 44929 | K4: =IF(J$4<EOMONTH($H$4,0),J4+1,"EOM") -> 44930 | L4: =IF(K$4<EOMONTH($H$4,0),K4+1,"EOM") -> 44931 | M4: =IF(L$4<EOMONTH($H$4,0),L4+1,"EOM") -> 44932 | N4: =IF(M$4<EOMONTH($H$4,0),M4+1,"EOM") -> 44933 | O4: =IF(N$4<EOMONTH($H$4,0),N4+1,"EOM") -> 44934 | P4: =IF(O$4<EOMONTH($H$4,0),O4+1,"EOM") -> 44935 | ... AL4: =IF(AK$4<EOMONTH($H$4,0),AK4+1,"EOM") -> 44957 | AM4: Total Leaves | AN4: Casual Leave | AO4: Privilaged Leave | AP4: Sick Leave | AQ4: Maternity or Paternity | AR4: Half Day | AS4: Work from Home | AT4: Holidays | AU4: Week Offs | AV4: Total Absent / No Show | AW4: Leave Without Pay
H5: =TEXT(H4,"DDD") -> Sun | I5: =TEXT(I4,"DDD") -> Mon | J5: =TEXT(J4,"DDD") -> Tue | K5: =TEXT(K4,"DDD") -> Wed | L5: =TEXT(L4,"DDD") -> Thu | M5: =TEXT(M4,"DDD") -> Fri | N5: =TEXT(N4,"DDD") -> Sat | O5: =TEXT(O4,"DDD") -> Sun | ... AL5: =TEXT(AL4,"DDD") -> Tue | AN5: CL | AO5: PL | AP5: SL | AQ5: ML | AR5: HD | AS5: WH | AT5: H | AU5: WO | AV5: A | AW5: LWP | AY5: Leaves | AZ5: Code
D6: 1 | AM6: =COUNTA(H6:AL6) -> 0 | AN6: =COUNTIF($H6:$AL6,AN$5) -> 0 | AO6: =COUNTIF($H6:$AL6,AO$5) -> 0 | AP6: =COUNTIF($H6:$AL6,AP$5) -> 0 | AQ6: =COUNTIF($H6:$AL6,AQ$5) -> 0 | AR6: =COUNTIF($H6:$AL6,AR$5) -> 0 | AS6: =COUNTIF($H6:$AL6,AS$5) -> 0 | AT6: =COUNTIF($H6:$AL6,AT$5) -> 0 | AU6: =COUNTIF($H6:$AL6,AU$5) -> 0 | ... AW6: =COUNTIF($H6:$AL6,AW$5) -> 0 | AY6: Casual Leave | AZ6: CL
D7: 2 | AM7: =COUNTA(H7:AL7) -> 0 | AN7: =COUNTIF($H7:$AL7,AN$5) -> 0 | AO7: =COUNTIF($H7:$AL7,AO$5) -> 0 | AP7: =COUNTIF($H7:$AL7,AP$5) -> 0 | AQ7: =COUNTIF($H7:$AL7,AQ$5) -> 0 | AR7: =COUNTIF($H7:$AL7,AR$5) -> 0 | AS7: =COUNTIF($H7:$AL7,AS$5) -> 0 | AT7: =COUNTIF($H7:$AL7,AT$5) -> 0 | AU7: =COUNTIF($H7:$AL7,AU$5) -> 0 | ... AW7: =COUNTIF($H7:$AL7,AW$5) -> 0 | AY7: Privilaged Leave | AZ7: PL
D8: 3 | AM8: =COUNTA(H8:AL8) -> 0 | AN8: =COUNTIF($H8:$AL8,AN$5) -> 0 | AO8: =COUNTIF($H8:$AL8,AO$5) -> 0 | AP8: =COUNTIF($H8:$AL8,AP$5) -> 0 | AQ8: =COUNTIF($H8:$AL8,AQ$5) -> 0 | AR8: =COUNTIF($H8:$AL8,AR$5) -> 0 | AS8: =COUNTIF($H8:$AL8,AS$5) -> 0 | AT8: =COUNTIF($H8:$AL8,AT$5) -> 0 | AU8: =COUNTIF($H8:$AL8,AU$5) -> 0 | ... AW8: =COUNTIF($H8:$AL8,AW$5) -> 0 | AY8: Sick Leave | AZ8: SL
D9: 4 | AM9: =COUNTA(H9:AL9) -> 0 | AN9: =COUNTIF($H9:$AL9,AN$5) -> 0 | AO9: =COUNTIF($H9:$AL9,AO$5) -> 0 | AP9: =COUNTIF($H9:$AL9,AP$5) -> 0 | AQ9: =COUNTIF($H9:$AL9,AQ$5) -> 0 | AR9: =COUNTIF($H9:$AL9,AR$5) -> 0 | AS9: =COUNTIF($H9:$AL9,AS$5) -> 0 | AT9: =COUNTIF($H9:$AL9,AT$5) -> 0 | AU9: =COUNTIF($H9:$AL9,AU$5) -> 0 | ... AW9: =COUNTIF($H9:$AL9,AW$5) -> 0 | AY9: Maternity or Paternity | AZ9: ML
D10: 5 | AM10: =COUNTA(H10:AL10) -> 0 | AN10: =COUNTIF($H10:$AL10,AN$5) -> 0 | AO10: =COUNTIF($H10:$AL10,AO$5) -> 0 | AP10: =COUNTIF($H10:$AL10,AP$5) -> 0 | AQ10: =COUNTIF($H10:$AL10,AQ$5) -> 0 | AR10: =COUNTIF($H10:$AL10,AR$5) -> 0 | AS10: =COUNTIF($H10:$AL10,AS$5) -> 0 | AT10: =COUNTIF($H10:$AL10,AT$5) -> 0 | AU10: =COUNTIF($H10:$AL10,AU$5) -> 0 | ... AW10: =COUNTIF($H10:$AL10,AW$5) -> 0 | AY10: Half Day | AZ10: HD
D11: 6 | AM11: =COUNTA(H11:AL11) -> 0 | AN11: =COUNTIF($H11:$AL11,AN$5) -> 0 | AO11: =COUNTIF($H11:$AL11,AO$5) -> 0 | AP11: =COUNTIF($H11:$AL11,AP$5) -> 0 | AQ11: =COUNTIF($H11:$AL11,AQ$5) -> 0 | AR11: =COUNTIF($H11:$AL11,AR$5) -> 0 | AS11: =COUNTIF($H11:$AL11,AS$5) -> 0 | AT11: =COUNTIF($H11:$AL11,AT$5) -> 0 | AU11: =COUNTIF($H11:$AL11,AU$5) -> 0 | ... AW11: =COUNTIF($H11:$AL11,AW$5) -> 0 | AY11: Work From Home | AZ11: WH
D12: 7 | AM12: =COUNTA(H12:AL12) -> 0 | AN12: =COUNTIF($H12:$AL12,AN$5) -> 0 | AO12: =COUNTIF($H12:$AL12,AO$5) -> 0 | AP12: =COUNTIF($H12:$AL12,AP$5) -> 0 | AQ12: =COUNTIF($H12:$AL12,AQ$5) -> 0 | AR12: =COUNTIF($H12:$AL12,AR$5) -> 0 | AS12: =COUNTIF($H12:$AL12,AS$5) -> 0 | AT12: =COUNTIF($H12:$AL12,AT$5) -> 0 | AU12: =COUNTIF($H12:$AL12,AU$5) -> 0 | ... AW12: =COUNTIF($H12:$AL12,AW$5) -> 0 | AY12: Holidays | AZ12: H
D13: 8 | AM13: =COUNTA(H13:AL13) -> 0 | AN13: =COUNTIF($H13:$AL13,AN$5) -> 0 | AO13: =COUNTIF($H13:$AL13,AO$5) -> 0 | AP13: =COUNTIF($H13:$AL13,AP$5) -> 0 | AQ13: =COUNTIF($H13:$AL13,AQ$5) -> 0 | AR13: =COUNTIF($H13:$AL13,AR$5) -> 0 | AS13: =COUNTIF($H13:$AL13,AS$5) -> 0 | AT13: =COUNTIF($H13:$AL13,AT$5) -> 0 | AU13: =COUNTIF($H13:$AL13,AU$5) -> 0 | ... AW13: =COUNTIF($H13:$AL13,AW$5) -> 0 | AY13: Week Offs | AZ13: WO
D14: 9 | AM14: =COUNTA(H14:AL14) -> 0 | AN14: =COUNTIF($H14:$AL14,AN$5) -> 0 | AO14: =COUNTIF($H14:$AL14,AO$5) -> 0 | AP14: =COUNTIF($H14:$AL14,AP$5) -> 0 | AQ14: =COUNTIF($H14:$AL14,AQ$5) -> 0 | AR14: =COUNTIF($H14:$AL14,AR$5) -> 0 | AS14: =COUNTIF($H14:$AL14,AS$5) -> 0 | AT14: =COUNTIF($H14:$AL14,AT$5) -> 0 | AU14: =COUNTIF($H14:$AL14,AU$5) -> 0 | ... AW14: =COUNTIF($H14:$AL14,AW$5) -> 0 | AY14: Absent / No Show | AZ14: A
D15: 10 | AM15: =COUNTA(H15:AL15) -> 0 | AN15: =COUNTIF($H15:$AL15,AN$5) -> 0 | AO15: =COUNTIF($H15:$AL15,AO$5) -> 0 | AP15: =COUNTIF($H15:$AL15,AP$5) -> 0 | AQ15: =COUNTIF($H15:$AL15,AQ$5) -> 0 | AR15: =COUNTIF($H15:$AL15,AR$5) -> 0 | AS15: =COUNTIF($H15:$AL15,AS$5) -> 0 | AT15: =COUNTIF($H15:$AL15,AT$5) -> 0 | AU15: =COUNTIF($H15:$AL15,AU$5) -> 0 | ... AW15: =COUNTIF($H15:$AL15,AW$5) -> 0 | AY15: Leave Without Pay | AZ15: LWP
D16: 11 | AM16: =COUNTA(H16:AL16) -> 0 | AN16: =COUNTIF($H16:$AL16,AN$5) -> 0 | AO16: =COUNTIF($H16:$AL16,AO$5) -> 0 | AP16: =COUNTIF($H16:$AL16,AP$5) -> 0 | AQ16: =COUNTIF($H16:$AL16,AQ$5) -> 0 | AR16: =COUNTIF($H16:$AL16,AR$5) -> 0 | AS16: =COUNTIF($H16:$AL16,AS$5) -> 0 | AT16: =COUNTIF($H16:$AL16,AT$5) -> 0 | AU16: =COUNTIF($H16:$AL16,AU$5) -> 0 | ... AW16: =COUNTIF($H16:$AL16,AW$5) -> 0
D17: 12 | AM17: =COUNTA(H17:AL17) -> 0 | AN17: =COUNTIF($H17:$AL17,AN$5) -> 0 | AO17: =COUNTIF($H17:$AL17,AO$5) -> 0 | AP17: =COUNTIF($H17:$AL17,AP$5) -> 0 | AQ17: =COUNTIF($H17:$AL17,AQ$5) -> 0 | AR17: =COUNTIF($H17:$AL17,AR$5) -> 0 | AS17: =COUNTIF($H17:$AL17,AS$5) -> 0 | AT17: =COUNTIF($H17:$AL17,AT$5) -> 0 | AU17: =COUNTIF($H17:$AL17,AU$5) -> 0 | ... AW17: =COUNTIF($H17:$AL17,AW$5) -> 0
D18: 13 | AM18: =COUNTA(H18:AL18) -> 0 | AN18: =COUNTIF($H18:$AL18,AN$5) -> 0 | AO18: =COUNTIF($H18:$AL18,AO$5) -> 0 | AP18: =COUNTIF($H18:$AL18,AP$5) -> 0 | AQ18: =COUNTIF($H18:$AL18,AQ$5) -> 0 | AR18: =COUNTIF($H18:$AL18,AR$5) -> 0 | AS18: =COUNTIF($H18:$AL18,AS$5) -> 0 | AT18: =COUNTIF($H18:$AL18,AT$5) -> 0 | AU18: =COUNTIF($H18:$AL18,AU$5) -> 0 | ... AW18: =COUNTIF($H18:$AL18,AW$5) -> 0
D19: 14 | AM19: =COUNTA(H19:AL19) -> 0 | AN19: =COUNTIF($H19:$AL19,AN$5) -> 0 | AO19: =COUNTIF($H19:$AL19,AO$5) -> 0 | AP19: =COUNTIF($H19:$AL19,AP$5) -> 0 | AQ19: =COUNTIF($H19:$AL19,AQ$5) -> 0 | AR19: =COUNTIF($H19:$AL19,AR$5) -> 0 | AS19: =COUNTIF($H19:$AL19,AS$5) -> 0 | AT19: =COUNTIF($H19:$AL19,AT$5) -> 0 | AU19: =COUNTIF($H19:$AL19,AU$5) -> 0 | ... AW19: =COUNTIF($H19:$AL19,AW$5) -> 0
D20: 15 | AM20: =COUNTA(H20:AL20) -> 0 | AN20: =COUNTIF($H20:$AL20,AN$5) -> 0 | AO20: =COUNTIF($H20:$AL20,AO$5) -> 0 | AP20: =COUNTIF($H20:$AL20,AP$5) -> 0 | AQ20: =COUNTIF($H20:$AL20,AQ$5) -> 0 | AR20: =COUNTIF($H20:$AL20,AR$5) -> 0 | AS20: =COUNTIF($H20:$AL20,AS$5) -> 0 | AT20: =COUNTIF($H20:$AL20,AT$5) -> 0 | AU20: =COUNTIF($H20:$AL20,AU$5) -> 0 | ... AW20: =COUNTIF($H20:$AL20,AW$5) -> 0
D21: 16 | AM21: =COUNTA(H21:AL21) -> 0 | AN21: =COUNTIF($H21:$AL21,AN$5) -> 0 | AO21: =COUNTIF($H21:$AL21,AO$5) -> 0 | AP21: =COUNTIF($H21:$AL21,AP$5) -> 0 | AQ21: =COUNTIF($H21:$AL21,AQ$5) -> 0 | AR21: =COUNTIF($H21:$AL21,AR$5) -> 0 | AS21: =COUNTIF($H21:$AL21,AS$5) -> 0 | AT21: =COUNTIF($H21:$AL21,AT$5) -> 0 | AU21: =COUNTIF($H21:$AL21,AU$5) -> 0 | ... AW21: =COUNTIF($H21:$AL21,AW$5) -> 0
D22: 17 | AM22: =COUNTA(H22:AL22) -> 0 | AN22: =COUNTIF($H22:$AL22,AN$5) -> 0 | AO22: =COUNTIF($H22:$AL22,AO$5) -> 0 | AP22: =COUNTIF($H22:$AL22,AP$5) -> 0 | AQ22: =COUNTIF($H22:$AL22,AQ$5) -> 0 | AR22: =COUNTIF($H22:$AL22,AR$5) -> 0 | AS22: =COUNTIF($H22:$AL22,AS$5) -> 0 | AT22: =COUNTIF($H22:$AL22,AT$5) -> 0 | AU22: =COUNTIF($H22:$AL22,AU$5) -> 0 | ... AW22: =COUNTIF($H22:$AL22,AW$5) -> 0
D23: 18 | AM23: =COUNTA(H23:AL23) -> 0 | AN23: =COUNTIF($H23:$AL23,AN$5) -> 0 | AO23: =COUNTIF($H23:$AL23,AO$5) -> 0 | AP23: =COUNTIF($H23:$AL23,AP$5) -> 0 | AQ23: =COUNTIF($H23:$AL23,AQ$5) -> 0 | AR23: =COUNTIF($H23:$AL23,AR$5) -> 0 | AS23: =COUNTIF($H23:$AL23,AS$5) -> 0 | AT23: =COUNTIF($H23:$AL23,AT$5) -> 0 | AU23: =COUNTIF($H23:$AL23,AU$5) -> 0 | ... AW23: =COUNTIF($H23:$AL23,AW$5) -> 0
D24: 19 | AM24: =COUNTA(H24:AL24) -> 0 | AN24: =COUNTIF($H24:$AL24,AN$5) -> 0 | AO24: =COUNTIF($H24:$AL24,AO$5) -> 0 | AP24: =COUNTIF($H24:$AL24,AP$5) -> 0 | AQ24: =COUNTIF($H24:$AL24,AQ$5) -> 0 | AR24: =COUNTIF($H24:$AL24,AR$5) -> 0 | AS24: =COUNTIF($H24:$AL24,AS$5) -> 0 | AT24: =COUNTIF($H24:$AL24,AT$5) -> 0 | AU24: =COUNTIF($H24:$AL24,AU$5) -> 0 | ... AW24: =COUNTIF($H24:$AL24,AW$5) -> 0
D25: 20 | AM25: =COUNTA(H25:AL25) -> 0 | AN25: =COUNTIF($H25:$AL25,AN$5) -> 0 | AO25: =COUNTIF($H25:$AL25,AO$5) -> 0 | AP25: =COUNTIF($H25:$AL25,AP$5) -> 0 | AQ25: =COUNTIF($H25:$AL25,AQ$5) -> 0 | AR25: =COUNTIF($H25:$AL25,AR$5) -> 0 | AS25: =COUNTIF($H25:$AL25,AS$5) -> 0 | AT25: =COUNTIF($H25:$AL25,AT$5) -> 0 | AU25: =COUNTIF($H25:$AL25,AU$5) -> 0 | ... AW25: =COUNTIF($H25:$AL25,AW$5) -> 0

Sheet Setting
B2: Dates | C2: Holiday List 2023 | E2: Emp. ID | F2: Name | G2: SCHOOL | I2: Leaves | J2: Code
B3: 45292 | C3: New Year | I3: Casual Leave | J3: CL
B4: 45306 | C4: MARTIN LUTHER KING | F4: SAMUEL | G4: WESTERVILLE | I4: Privilaged Leave | J4: PL
B5: 45341 | C5: PRESIDENTS DAY | F5: LILY | G5: DELAWARE | I5: Sick Leave | J5: SL
B6: 45382 | C6: EASTER SUNDAY | F6: WILLIAM | G6: WESTERVILLE | I6: Maternity or Paternity | J6: ML
B7: 45439 | C7: MEMORIAL DAY | I7: Half Day | J7: HD
B8: 45459 | C8: FATHERS DAY | I8: Work From Home | J8: WH
B9: 45477 | C9: Independence Day | I9: Holidays | J9: H
B10: 45537 | C10: Labor Day | I10: Week Offs | J10: WO
B11: 45579 | C11: COLUMBUS DAY | I11: Absent / No Show | J11: A
B12: 45601 | C12: ELECTION DAY | I12: Leave Without Pay | J12: LWP
B13: 45607 | C13: VETERANS DAY
B14: 45624 | C14: THANKSGIVING DAY
B15: 45625 | C15: BLACK FRIDAY
B16: 45650 | C16: Christmas Eve
B17: 45651 | C17: Christmas Day
B18: 45657 | C18: New Years Eve
B19: 45658 | C19: New Years Day
B20: 45677 | C20: MARTIN LUTHER KING
B21: 45705 | C21: PRESIDENTS DAY
B22: 45767 | C22: EASTER SUNDAY
B23: 45788 | C23: Mothers Day
B24: 45803 | C24: MEMORIAL DAY
... B26: 45842 | C26: Independence Day

Sheet January
I2: Monthly Leave Tracker
F3: January | G3: 2023 | H3: =IFERROR(VLOOKUP(H4,Holidays,2,0),"") | I3: =IFERROR(VLOOKUP(I4,Holidays,2,0),"") | J3: =IFERROR(VLOOKUP(J4,Holidays,2,0),"") | K3: =IFERROR(VLOOKUP(K4,Holidays,2,0),"") | L3: =IFERROR(VLOOKUP(L4,Holidays,2,0),"") | M3: =IFERROR(VLOOKUP(M4,Holidays,2,0),"") | N3: =IFERROR(VLOOKUP(N4,Holidays,2,0),"") | O3: =IFERROR(VLOOKUP(O4,Holidays,2,0),"") | ... AL3: =IFERROR(VLOOKUP(AL4,Holidays,2,0),"") | AM3: Summary
D4: SL. No. | E4: Emp. Code | F4: Employee Name | G4: Designation | H4: =DATEVALUE("1"&F3&G3) -> 44927 | I4: =IF(H$4<EOMONTH($H$4,0),H4+1,"EOM") -> 44928 | J4: =IF(I$4<EOMONTH($H$4,0),I4+1,"EOM") -> 44929 | K4: =IF(J$4<EOMONTH($H$4,0),J4+1,"EOM") -> 44930 | L4: =IF(K$4<EOMONTH($H$4,0),K4+1,"EOM") -> 44931 | M4: =IF(L$4<EOMONTH($H$4,0),L4+1,"EOM") -> 44932 | N4: =IF(M$4<EOMONTH($H$4,0),M4+1,"EOM") -> 44933 | O4: =IF(N$4<EOMONTH($H$4,0),N4+1,"EOM") -> 44934 | P4: =IF(O$4<EOMONTH($H$4,0),O4+1,"EOM") -> 44935 | ... AL4: =IF(AK$4<EOMONTH($H$4,0),AK4+1,"EOM") -> 44957 | AM4: Total Leaves | AN4: Casual Leave | AO4: Privilaged Leave | AP4: Sick Leave | AQ4: Maternity or Paternity | AR4: Half Day | AS4: Work from Home | AT4: Holidays | AU4: Week Offs | AV4: Total Absent / No Show | AW4: Leave Without Pay
H5: =TEXT(H4,"DDD") -> Sun | I5: =TEXT(I4,"DDD") -> Mon | J5: =TEXT(J4,"DDD") -> Tue | K5: =TEXT(K4,"DDD") -> Wed | L5: =TEXT(L4,"DDD") -> Thu | M5: =TEXT(M4,"DDD") -> Fri | N5: =TEXT(N4,"DDD") -> Sat | O5: =TEXT(O4,"DDD") -> Sun | ... AL5: =TEXT(AL4,"DDD") -> Tue | AN5: CL | AO5: PL | AP5: SL | AQ5: ML | AR5: HD | AS5: WH | AT5: H | AU5: WO | AV5: A | AW5: LWP
D6: 1 | E6: =Setting!E4 | F6: =IFERROR(VLOOKUP(E6,Setting!$E:$G,2,0),"") | G6: =IFERROR(VLOOKUP(E6,Setting!$E:$G,3,0),"") | AM6: =SUM(AN6:AW6) -> 0 | AN6: =COUNTIF($H6:$AL6,AN$5) -> 0 | AO6: =COUNTIF($H6:$AL6,AO$5) -> 0 | AP6: =COUNTIF($H6:$AL6,AP$5) -> 0 | AQ6: =COUNTIF($H6:$AL6,AQ$5) -> 0 | AR6: =COUNTIF($H6:$AL6,AR$5) -> 0 | AS6: =COUNTIF($H6:$AL6,AS$5) -> 0 | AT6: =COUNTIF($H6:$AL6,AT$5) -> 0 | AU6: =COUNTIF($H6:$AL6,AU$5) -> 0 | ... AW6: =COUNTIF($H6:$AL6,AW$5) -> 0
D7: 2 | E7: =Setting!E5 | F7: =IFERROR(VLOOKUP(E7,Setting!$E:$G,2,0),"") | G7: =IFERROR(VLOOKUP(E7,Setting!$E:$G,3,0),"") | AM7: =SUM(AN7:AW7) -> 0 | AN7: =COUNTIF($H7:$AL7,AN$5) -> 0 | AO7: =COUNTIF($H7:$AL7,AO$5) -> 0 | AP7: =COUNTIF($H7:$AL7,AP$5) -> 0 | AQ7: =COUNTIF($H7:$AL7,AQ$5) -> 0 | AR7: =COUNTIF($H7:$AL7,AR$5) -> 0 | AS7: =COUNTIF($H7:$AL7,AS$5) -> 0 | AT7: =COUNTIF($H7:$AL7,AT$5) -> 0 | AU7: =COUNTIF($H7:$AL7,AU$5) -> 0 | ... AW7: =COUNTIF($H7:$AL7,AW$5) -> 0
D8: 3 | E8: =Setting!E6 | F8: =IFERROR(VLOOKUP(E8,Setting!$E:$G,2,0),"") | G8: =IFERROR(VLOOKUP(E8,Setting!$E:$G,3,0),"") | AM8: =SUM(AN8:AW8) -> 0 | AN8: =COUNTIF($H8:$AL8,AN$5) -> 0 | AO8: =COUNTIF($H8:$AL8,AO$5) -> 0 | AP8: =COUNTIF($H8:$AL8,AP$5) -> 0 | AQ8: =COUNTIF($H8:$AL8,AQ$5) -> 0 | AR8: =COUNTIF($H8:$AL8,AR$5) -> 0 | AS8: =COUNTIF($H8:$AL8,AS$5) -> 0 | AT8: =COUNTIF($H8:$AL8,AT$5) -> 0 | AU8: =COUNTIF($H8:$AL8,AU$5) -> 0 | ... AW8: =COUNTIF($H8:$AL8,AW$5) -> 0
D9: 4 | E9: =Setting!E7 | F9: =IFERROR(VLOOKUP(E9,Setting!$E:$G,2,0),"") | G9: =IFERROR(VLOOKUP(E9,Setting!$E:$G,3,0),"") | AM9: =SUM(AN9:AW9) -> 0 | AN9: =COUNTIF($H9:$AL9,AN$5) -> 0 | AO9: =COUNTIF($H9:$AL9,AO$5) -> 0 | AP9: =COUNTIF($H9:$AL9,AP$5) -> 0 | AQ9: =COUNTIF($H9:$AL9,AQ$5) -> 0 | AR9: =COUNTIF($H9:$AL9,AR$5) -> 0 | AS9: =COUNTIF($H9:$AL9,AS$5) -> 0 | AT9: =COUNTIF($H9:$AL9,AT$5) -> 0 | AU9: =COUNTIF($H9:$AL9,AU$5) -> 0 | ... AW9: =COUNTIF($H9:$AL9,AW$5) -> 0
D10: 5 | E10: =Setting!E8 | F10: =IFERROR(VLOOKUP(E10,Setting!$E:$G,2,0),"") | G10: =IFERROR(VLOOKUP(E10,Setting!$E:$G,3,0),"") | AM10: =SUM(AN10:AW10) -> 0 | AN10: =COUNTIF($H10:$AL10,AN$5) -> 0 | AO10: =COUNTIF($H10:$AL10,AO$5) -> 0 | AP10: =COUNTIF($H10:$AL10,AP$5) -> 0 | AQ10: =COUNTIF($H10:$AL10,AQ$5) -> 0 | AR10: =COUNTIF($H10:$AL10,AR$5) -> 0 | AS10: =COUNTIF($H10:$AL10,AS$5) -> 0 | AT10: =COUNTIF($H10:$AL10,AT$5) -> 0 | AU10: =COUNTIF($H10:$AL10,AU$5) -> 0 | ... AW10: =COUNTIF($H10:$AL10,AW$5) -> 0
D11: 6 | E11: =Setting!E9 | F11: =IFERROR(VLOOKUP(E11,Setting!$E:$G,2,0),"") | G11: =IFERROR(VLOOKUP(E11,Setting!$E:$G,3,0),"") | AM11: =SUM(AN11:AW11) -> 0 | AN11: =COUNTIF($H11:$AL11,AN$5) -> 0 | AO11: =COUNTIF($H11:$AL11,AO$5) -> 0 | AP11: =COUNTIF($H11:$AL11,AP$5) -> 0 | AQ11: =COUNTIF($H11:$AL11,AQ$5) -> 0 | AR11: =COUNTIF($H11:$AL11,AR$5) -> 0 | AS11: =COUNTIF($H11:$AL11,AS$5) -> 0 | AT11: =COUNTIF($H11:$AL11,AT$5) -> 0 | AU11: =COUNTIF($H11:$AL11,AU$5) -> 0 | ... AW11: =COUNTIF($H11:$AL11,AW$5) -> 0
D12: 7 | E12: =Setting!E10 | F12: =IFERROR(VLOOKUP(E12,Setting!$E:$G,2,0),"") | G12: =IFERROR(VLOOKUP(E12,Setting!$E:$G,3,0),"") | AM12: =SUM(AN12:AW12) -> 0 | AN12: =COUNTIF($H12:$AL12,AN$5) -> 0 | AO12: =COUNTIF($H12:$AL12,AO$5) -> 0 | AP12: =COUNTIF($H12:$AL12,AP$5) -> 0 | AQ12: =COUNTIF($H12:$AL12,AQ$5) -> 0 | AR12: =COUNTIF($H12:$AL12,AR$5) -> 0 | AS12: =COUNTIF($H12:$AL12,AS$5) -> 0 | AT12: =COUNTIF($H12:$AL12,AT$5) -> 0 | AU12: =COUNTIF($H12:$AL12,AU$5) -> 0 | ... AW12: =COUNTIF($H12:$AL12,AW$5) -> 0
D13: 8 | E13: =Setting!E11 | F13: =IFERROR(VLOOKUP(E13,Setting!$E:$G,2,0),"") | G13: =IFERROR(VLOOKUP(E13,Setting!$E:$G,3,0),"") | AM13: =SUM(AN13:AW13) -> 0 | AN13: =COUNTIF($H13:$AL13,AN$5) -> 0 | AO13: =COUNTIF($H13:$AL13,AO$5) -> 0 | AP13: =COUNTIF($H13:$AL13,AP$5) -> 0 | AQ13: =COUNTIF($H13:$AL13,AQ$5) -> 0 | AR13: =COUNTIF($H13:$AL13,AR$5) -> 0 | AS13: =COUNTIF($H13:$AL13,AS$5) -> 0 | AT13: =COUNTIF($H13:$AL13,AT$5) -> 0 | AU13: =COUNTIF($H13:$AL13,AU$5) -> 0 | ... AW13: =COUNTIF($H13:$AL13,AW$5) -> 0
D14: 9 | E14: =Setting!E12 | F14: =IFERROR(VLOOKUP(E14,Setting!$E:$G,2,0),"") | G14: =IFERROR(VLOOKUP(E14,Setting!$E:$G,3,0),"") | AM14: =SUM(AN14:AW14) -> 0 | AN14: =COUNTIF($H14:$AL14,AN$5) -> 0 | AO14: =COUNTIF($H14:$AL14,AO$5) -> 0 | AP14: =COUNTIF($H14:$AL14,AP$5) -> 0 | AQ14: =COUNTIF($H14:$AL14,AQ$5) -> 0 | AR14: =COUNTIF($H14:$AL14,AR$5) -> 0 | AS14: =COUNTIF($H14:$AL14,AS$5) -> 0 | AT14: =COUNTIF($H14:$AL14,AT$5) -> 0 | AU14: =COUNTIF($H14:$AL14,AU$5) -> 0 | ... AW14: =COUNTIF($H14:$AL14,AW$5) -> 0
D15: 10 | E15: =Setting!E13 | F15: =IFERROR(VLOOKUP(E15,Setting!$E:$G,2,0),"") | G15: =IFERROR(VLOOKUP(E15,Setting!$E:$G,3,0),"") | AM15: =SUM(AN15:AW15) -> 0 | AN15: =COUNTIF($H15:$AL15,AN$5) -> 0 | AO15: =COUNTIF($H15:$AL15,AO$5) -> 0 | AP15: =COUNTIF($H15:$AL15,AP$5) -> 0 | AQ15: =COUNTIF($H15:$AL15,AQ$5) -> 0 | AR15: =COUNTIF($H15:$AL15,AR$5) -> 0 | AS15: =COUNTIF($H15:$AL15,AS$5) -> 0 | AT15: =COUNTIF($H15:$AL15,AT$5) -> 0 | AU15: =COUNTIF($H15:$AL15,AU$5) -> 0 | ... AW15: =COUNTIF($H15:$AL15,AW$5) -> 0
D16: 11 | E16: =Setting!E14 | F16: =IFERROR(VLOOKUP(E16,Setting!$E:$G,2,0),"") | G16: =IFERROR(VLOOKUP(E16,Setting!$E:$G,3,0),"") | AM16: =SUM(AN16:AW16) -> 0 | AN16: =COUNTIF($H16:$AL16,AN$5) -> 0 | AO16: =COUNTIF($H16:$AL16,AO$5) -> 0 | AP16: =COUNTIF($H16:$AL16,AP$5) -> 0 | AQ16: =COUNTIF($H16:$AL16,AQ$5) -> 0 | AR16: =COUNTIF($H16:$AL16,AR$5) -> 0 | AS16: =COUNTIF($H16:$AL16,AS$5) -> 0 | AT16: =COUNTIF($H16:$AL16,AT$5) -> 0 | AU16: =COUNTIF($H16:$AL16,AU$5) -> 0 | ... AW16: =COUNTIF($H16:$AL16,AW$5) -> 0
D17: 12 | E17: =Setting!E15 | F17: =IFERROR(VLOOKUP(E17,Setting!$E:$G,2,0),"") | G17: =IFERROR(VLOOKUP(E17,Setting!$E:$G,3,0),"") | AM17: =SUM(AN17:AW17) -> 0 | AN17: =COUNTIF($H17:$AL17,AN$5) -> 0 | AO17: =COUNTIF($H17:$AL17,AO$5) -> 0 | AP17: =COUNTIF($H17:$AL17,AP$5) -> 0 | AQ17: =COUNTIF($H17:$AL17,AQ$5) -> 0 | AR17: =COUNTIF($H17:$AL17,AR$5) -> 0 | AS17: =COUNTIF($H17:$AL17,AS$5) -> 0 | AT17: =COUNTIF($H17:$AL17,AT$5) -> 0 | AU17: =COUNTIF($H17:$AL17,AU$5) -> 0 | ... AW17: =COUNTIF($H17:$AL17,AW$5) -> 0
... D25: 20 | E25: =Setting!E23 | F25: =IFERROR(VLOOKUP(E25,Setting!$E:$G,2,0),"") | G25: =IFERROR(VLOOKUP(E25,Setting!$E:$G,3,0),"") | AM25: =SUM(AN25:AW25) -> 0 | AN25: =COUNTIF($H25:$AL25,AN$5) -> 0 | AO25: =COUNTIF($H25:$AL25,AO$5) -> 0 | AP25: =COUNTIF($H25:$AL25,AP$5) -> 0 | AQ25: =COUNTIF($H25:$AL25,AQ$5) -> 0 | AR25: =COUNTIF($H25:$AL25,AR$5) -> 0 | AS25: =COUNTIF($H25:$AL25,AS$5) -> 0 | AT25: =COUNTIF($H25:$AL25,AT$5) -> 0 | AU25: =COUNTIF($H25:$AL25,AU$5) -> 0 | ... AW25: =COUNTIF($H25:$AL25,AW$5) -> 0

Sheet February
I2: Monthly Leave Tracker
F3: February | G3: 2023 | H3: =IFERROR(VLOOKUP(H4,Holidays,2,0),"") | I3: =IFERROR(VLOOKUP(I4,Holidays,2,0),"") | J3: =IFERROR(VLOOKUP(J4,Holidays,2,0),"") | K3: =IFERROR(VLOOKUP(K4,Holidays,2,0),"") | L3: =IFERROR(VLOOKUP(L4,Holidays,2,0),"") | M3: =IFERROR(VLOOKUP(M4,Holidays,2,0),"") | N3: =IFERROR(VLOOKUP(N4,Holidays,2,0),"") | O3: =IFERROR(VLOOKUP(O4,Holidays,2,0),"") | ... AL3: =IFERROR(VLOOKUP(AL4,Holidays,2,0),"") | AM3: Summary
D4: SL. No. | E4: Emp. Code | F4: Employee Name | G4: Designation | H4: =DATEVALUE("1"&F3&G3) -> 44958 | I4: =IF(H$4<EOMONTH($H$4,0),H4+1,"EOM") -> 44959 | J4: =IF(I$4<EOMONTH($H$4,0),I4+1,"EOM") -> 44960 | K4: =IF(J$4<EOMONTH($H$4,0),J4+1,"EOM") -> 44961 | L4: =IF(K$4<EOMONTH($H$4,0),K4+1,"EOM") -> 44962 | M4: =IF(L$4<EOMONTH($H$4,0),L4+1,"EOM") -> 44963 | N4: =IF(M$4<EOMONTH($H$4,0),M4+1,"EOM") -> 44964 | O4: =IF(N$4<EOMONTH($H$4,0),N4+1,"EOM") -> 44965 | P4: =IF(O$4<EOMONTH($H$4,0),O4+1,"EOM") -> 44966 | ... AL4: =IF(AK$4<EOMONTH($H$4,0),AK4+1,"EOM") -> EOM | AM4: Total Leaves | AN4: Casual Leave | AO4: Privilaged Leave | AP4: Sick Leave | AQ4: Maternity or Paternity | AR4: Half Day | AS4: Work from Home | AT4: Holidays | AU4: Week Offs | AV4: Total Absent / No Show | AW4: Leave Without Pay
H5: =TEXT(H4,"DDD") -> Wed | I5: =TEXT(I4,"DDD") -> Thu | J5: =TEXT(J4,"DDD") -> Fri | K5: =TEXT(K4,"DDD") -> Sat | L5: =TEXT(L4,"DDD") -> Sun | M5: =TEXT(M4,"DDD") -> Mon | N5: =TEXT(N4,"DDD") -> Tue | O5: =TEXT(O4,"DDD") -> Wed | ... AL5: =TEXT(AL4,"DDD") -> EOM | AN5: CL | AO5: PL | AP5: SL | AQ5: ML | AR5: HD | AS5: WH | AT5: H | AU5: WO | AV5: A | AW5: LWP
D6: 1 | E6: =Setting!E4 | F6: =IFERROR(VLOOKUP(E6,Setting!$E:$G,2,0),"") | G6: =IFERROR(VLOOKUP(E6,Setting!$E:$G,3,0),"") | AM6: =SUM(AN6:AW6) -> 0 | AN6: =COUNTIF($H6:$AL6,AN$5) -> 0 | AO6: =COUNTIF($H6:$AL6,AO$5) -> 0 | AP6: =COUNTIF($H6:$AL6,AP$5) -> 0 | AQ6: =COUNTIF($H6:$AL6,AQ$5) -> 0 | AR6: =COUNTIF($H6:$AL6,AR$5) -> 0 | AS6: =COUNTIF($H6:$AL6,AS$5) -> 0 | AT6: =COUNTIF($H6:$AL6,AT$5) -> 0 | AU6: =COUNTIF($H6:$AL6,AU$5) -> 0 | ... AW6: =COUNTIF($H6:$AL6,AW$5) -> 0
D7: 2 | E7: =Setting!E5 | F7: =IFERROR(VLOOKUP(E7,Setting!$E:$G,2,0),"") | G7: =IFERROR(VLOOKUP(E7,Setting!$E:$G,3,0),"") | AM7: =SUM(AN7:AW7) -> 0 | AN7: =COUNTIF($H7:$AL7,AN$5) -> 0 | AO7: =COUNTIF($H7:$AL7,AO$5) -> 0 | AP7: =COUNTIF($H7:$AL7,AP$5) -> 0 | AQ7: =COUNTIF($H7:$AL7,AQ$5) -> 0 | AR7: =COUNTIF($H7:$AL7,AR$5) -> 0 | AS7: =COUNTIF($H7:$AL7,AS$5) -> 0 | AT7: =COUNTIF($H7:$AL7,AT$5) -> 0 | AU7: =COUNTIF($H7:$AL7,AU$5) -> 0 | ... AW7: =COUNTIF($H7:$AL7,AW$5) -> 0
D8: 3 | E8: =Setting!E6 | F8: =IFERROR(VLOOKUP(E8,Setting!$E:$G,2,0),"") | G8: =IFERROR(VLOOKUP(E8,Setting!$E:$G,3,0),"") | AM8: =SUM(AN8:AW8) -> 0 | AN8: =COUNTIF($H8:$AL8,AN$5) -> 0 | AO8: =COUNTIF($H8:$AL8,AO$5) -> 0 | AP8: =COUNTIF($H8:$AL8,AP$5) -> 0 | AQ8: =COUNTIF($H8:$AL8,AQ$5) -> 0 | AR8: =COUNTIF($H8:$AL8,AR$5) -> 0 | AS8: =COUNTIF($H8:$AL8,AS$5) -> 0 | AT8: =COUNTIF($H8:$AL8,AT$5) -> 0 | AU8: =COUNTIF($H8:$AL8,AU$5) -> 0 | ... AW8: =COUNTIF($H8:$AL8,AW$5) -> 0
D9: 4 | E9: =Setting!E7 | F9: =IFERROR(VLOOKUP(E9,Setting!$E:$G,2,0),"") | G9: =IFERROR(VLOOKUP(E9,Setting!$E:$G,3,0),"") | AM9: =SUM(AN9:AW9) -> 0 | AN9: =COUNTIF($H9:$AL9,AN$5) -> 0 | AO9: =COUNTIF($H9:$AL9,AO$5) -> 0 | AP9: =COUNTIF($H9:$AL9,AP$5) -> 0 | AQ9: =COUNTIF($H9:$AL9,AQ$5) -> 0 | AR9: =COUNTIF($H9:$AL9,AR$5) -> 0 | AS9: =COUNTIF($H9:$AL9,AS$5) -> 0 | AT9: =COUNTIF($H9:$AL9,AT$5) -> 0 | AU9: =COUNTIF($H9:$AL9,AU$5) -> 0 | ... AW9: =COUNTIF($H9:$AL9,AW$5) -> 0
D10: 5 | E10: =Setting!E8 | F10: =IFERROR(VLOOKUP(E10,Setting!$E:$G,2,0),"") | G10: =IFERROR(VLOOKUP(E10,Setting!$E:$G,3,0),"") | AM10: =SUM(AN10:AW10) -> 0 | AN10: =COUNTIF($H10:$AL10,AN$5) -> 0 | AO10: =COUNTIF($H10:$AL10,AO$5) -> 0 | AP10: =COUNTIF($H10:$AL10,AP$5) -> 0 | AQ10: =COUNTIF($H10:$AL10,AQ$5) -> 0 | AR10: =COUNTIF($H10:$AL10,AR$5) -> 0 | AS10: =COUNTIF($H10:$AL10,AS$5) -> 0 | AT10: =COUNTIF($H10:$AL10,AT$5) -> 0 | AU10: =COUNTIF($H10:$AL10,AU$5) -> 0 | ... AW10: =COUNTIF($H10:$AL10,AW$5) -> 0
D11: 6 | E11: =Setting!E9 | F11: =IFERROR(VLOOKUP(E11,Setting!$E:$G,2,0),"") | G11: =IFERROR(VLOOKUP(E11,Setting!$E:$G,3,0),"") | AM11: =SUM(AN11:AW11) -> 0 | AN11: =COUNTIF($H11:$AL11,AN$5) -> 0 | AO11: =COUNTIF($H11:$AL11,AO$5) -> 0 | AP11: =COUNTIF($H11:$AL11,AP$5) -> 0 | AQ11: =COUNTIF($H11:$AL11,AQ$5) -> 0 | AR11: =COUNTIF($H11:$AL11,AR$5) -> 0 | AS11: =COUNTIF($H11:$AL11,AS$5) -> 0 | AT11: =COUNTIF($H11:$AL11,AT$5) -> 0 | AU11: =COUNTIF($H11:$AL11,AU$5) -> 0 | ... AW11: =COUNTIF($H11:$AL11,AW$5) -> 0
D12: 7 | E12: =Setting!E10 | F12: =IFERROR(VLOOKUP(E12,Setting!$E:$G,2,0),"") | G12: =IFERROR(VLOOKUP(E12,Setting!$E:$G,3,0),"") | AM12: =SUM(AN12:AW12) -> 0 | AN12: =COUNTIF($H12:$AL12,AN$5) -> 0 | AO12: =COUNTIF($H12:$AL12,AO$5) -> 0 | AP12: =COUNTIF($H12:$AL12,AP$5) -> 0 | AQ12: =COUNTIF($H12:$AL12,AQ$5) -> 0 | AR12: =COUNTIF($H12:$AL12,AR$5) -> 0 | AS12: =COUNTIF($H12:$AL12,AS$5) -> 0 | AT12: =COUNTIF($H12:$AL12,AT$5) -> 0 | AU12: =COUNTIF($H12:$AL12,AU$5) -> 0 | ... AW12: =COUNTIF($H12:$AL12,AW$5) -> 0
D13: 8 | E13: =Setting!E11 | F13: =IFERROR(VLOOKUP(E13,Setting!$E:$G,2,0),"") | G13: =IFERROR(VLOOKUP(E13,Setting!$E:$G,3,0),"") | AM13: =SUM(AN13:AW13) -> 0 | AN13: =COUNTIF($H13:$AL13,AN$5) -> 0 | AO13: =COUNTIF($H13:$AL13,AO$5) -> 0 | AP13: =COUNTIF($H13:$AL13,AP$5) -> 0 | AQ13: =COUNTIF($H13:$AL13,AQ$5) -> 0 | AR13: =COUNTIF($H13:$AL13,AR$5) -> 0 | AS13: =COUNTIF($H13:$AL13,AS$5) -> 0 | AT13: =COUNTIF($H13:$AL13,AT$5) -> 0 | AU13: =COUNTIF($H13:$AL13,AU$5) -> 0 | ... AW13: =COUNTIF($H13:$AL13,AW$5) -> 0
D14: 9 | E14: =Setting!E12 | F14: =IFERROR(VLOOKUP(E14,Setting!$E:$G,2,0),"") | G14: =IFERROR(VLOOKUP(E14,Setting!$E:$G,3,0),"") | AM14: =SUM(AN14:AW14) -> 0 | AN14: =COUNTIF($H14:$AL14,AN$5) -> 0 | AO14: =COUNTIF($H14:$AL14,AO$5) -> 0 | AP14: =COUNTIF($H14:$AL14,AP$5) -> 0 | AQ14: =COUNTIF($H14:$AL14,AQ$5) -> 0 | AR14: =COUNTIF($H14:$AL14,AR$5) -> 0 | AS14: =COUNTIF($H14:$AL14,AS$5) -> 0 | AT14: =COUNTIF($H14:$AL14,AT$5) -> 0 | AU14: =COUNTIF($H14:$AL14,AU$5) -> 0 | ... AW14: =COUNTIF($H14:$AL14,AW$5) -> 0
D15: 10 | E15: =Setting!E13 | F15: =IFERROR(VLOOKUP(E15,Setting!$E:$G,2,0),"") | G15: =IFERROR(VLOOKUP(E15,Setting!$E:$G,3,0),"") | AM15: =SUM(AN15:AW15) -> 0 | AN15: =COUNTIF($H15:$AL15,AN$5) -> 0 | AO15: =COUNTIF($H15:$AL15,AO$5) -> 0 | AP15: =COUNTIF($H15:$AL15,AP$5) -> 0 | AQ15: =COUNTIF($H15:$AL15,AQ$5) -> 0 | AR15: =COUNTIF($H15:$AL15,AR$5) -> 0 | AS15: =COUNTIF($H15:$AL15,AS$5) -> 0 | AT15: =COUNTIF($H15:$AL15,AT$5) -> 0 | AU15: =COUNTIF($H15:$AL15,AU$5) -> 0 | ... AW15: =COUNTIF($H15:$AL15,AW$5) -> 0
D16: 11 | E16: =Setting!E14 | F16: =IFERROR(VLOOKUP(E16,Setting!$E:$G,2,0),"") | G16: =IFERROR(VLOOKUP(E16,Setting!$E:$G,3,0),"") | AM16: =SUM(AN16:AW16) -> 0 | AN16: =COUNTIF($H16:$AL16,AN$5) -> 0 | AO16: =COUNTIF($H16:$AL16,AO$5) -> 0 | AP16: =COUNTIF($H16:$AL16,AP$5) -> 0 | AQ16: =COUNTIF($H16:$AL16,AQ$5) -> 0 | AR16: =COUNTIF($H16:$AL16,AR$5) -> 0 | AS16: =COUNTIF($H16:$AL16,AS$5) -> 0 | AT16: =COUNTIF($H16:$AL16,AT$5) -> 0 | AU16: =COUNTIF($H16:$AL16,AU$5) -> 0 | ... AW16: =COUNTIF($H16:$AL16,AW$5) -> 0
D17: 12 | E17: =Setting!E15 | F17: =IFERROR(VLOOKUP(E17,Setting!$E:$G,2,0),"") | G17: =IFERROR(VLOOKUP(E17,Setting!$E:$G,3,0),"") | AM17: =SUM(AN17:AW17) -> 0 | AN17: =COUNTIF($H17:$AL17,AN$5) -> 0 | AO17: =COUNTIF($H17:$AL17,AO$5) -> 0 | AP17: =COUNTIF($H17:$AL17,AP$5) -> 0 | AQ17: =COUNTIF($H17:$AL17,AQ$5) -> 0 | AR17: =COUNTIF($H17:$AL17,AR$5) -> 0 | AS17: =COUNTIF($H17:$AL17,AS$5) -> 0 | AT17: =COUNTIF($H17:$AL17,AT$5) -> 0 | AU17: =COUNTIF($H17:$AL17,AU$5) -> 0 | ... AW17: =COUNTIF($H17:$AL17,AW$5) -> 0
... D25: 20 | E25: =Setting!E23 | F25: =IFERROR(VLOOKUP(E25,Setting!$E:$G,2,0),"") | G25: =IFERROR(VLOOKUP(E25,Setting!$E:$G,3,0),"") | AM25: =SUM(AN25:AW25) -> 0 | AN25: =COUNTIF($H25:$AL25,AN$5) -> 0 | AO25: =COUNTIF($H25:$AL25,AO$5) -> 0 | AP25: =COUNTIF($H25:$AL25,AP$5) -> 0 | AQ25: =COUNTIF($H25:$AL25,AQ$5) -> 0 | AR25: =COUNTIF($H25:$AL25,AR$5) -> 0 | AS25: =COUNTIF($H25:$AL25,AS$5) -> 0 | AT25: =COUNTIF($H25:$AL25,AT$5) -> 0 | AU25: =COUNTIF($H25:$AL25,AU$5) -> 0 | ... AW25: =COUNTIF($H25:$AL25,AW$5) -> 0

Sheet March
I2: Monthly Leave Tracker
F3: March | G3: 2023 | H3: =IFERROR(VLOOKUP(H4,Holidays,2,0),"") | I3: =IFERROR(VLOOKUP(I4,Holidays,2,0),"") | J3: =IFERROR(VLOOKUP(J4,Holidays,2,0),"") | K3: =IFERROR(VLOOKUP(K4,Holidays,2,0),"") | L3: =IFERROR(VLOOKUP(L4,Holidays,2,0),"") | M3: =IFERROR(VLOOKUP(M4,Holidays,2,0),"") | N3: =IFERROR(VLOOKUP(N4,Holidays,2,0),"") | O3: =IFERROR(VLOOKUP(O4,Holidays,2,0),"") | ... AL3: =IFERROR(VLOOKUP(AL4,Holidays,2,0),"") | AM3: Summary
D4: SL. No. | E4: Emp. Code | F4: Employee Name | G4: Designation | H4: =DATEVALUE("1"&F3&G3) -> 44986 | I4: =IF(H$4<EOMONTH($H$4,0),H4+1,"EOM") -> 44987 | J4: =IF(I$4<EOMONTH($H$4,0),I4+1,"EOM") -> 44988 | K4: =IF(J$4<EOMONTH($H$4,0),J4+1,"EOM") -> 44989 | L4: =IF(K$4<EOMONTH($H$4,0),K4+1,"EOM") -> 44990 | M4: =IF(L$4<EOMONTH($H$4,0),L4+1,"EOM") -> 44991 | N4: =IF(M$4<EOMONTH($H$4,0),M4+1,"EOM") -> 44992 | O4: =IF(N$4<EOMONTH($H$4,0),N4+1,"EOM") -> 44993 | P4: =IF(O$4<EOMONTH($H$4,0),O4+1,"EOM") -> 44994 | ... AL4: =IF(AK$4<EOMONTH($H$4,0),AK4+1,"EOM") -> 45016 | AM4: Total Leaves | AN4: Casual Leave | AO4: Privilaged Leave | AP4: Sick Leave | AQ4: Maternity or Paternity | AR4: Half Day | AS4: Work from Home | AT4: Holidays | AU4: Week Offs | AV4: Total Absent / No Show | AW4: Leave Without Pay
H5: =TEXT(H4,"DDD") -> Wed | I5: =TEXT(I4,"DDD") -> Thu | J5: =TEXT(J4,"DDD") -> Fri | K5: =TEXT(K4,"DDD") -> Sat | L5: =TEXT(L4,"DDD") -> Sun | M5: =TEXT(M4,"DDD") -> Mon | N5: =TEXT(N4,"DDD") -> Tue | O5: =TEXT(O4,"DDD") -> Wed | ... AL5: =TEXT(AL4,"DDD") -> Fri | AN5: CL | AO5: PL | AP5: SL | AQ5: ML | AR5: HD | AS5: WH | AT5: H | AU5: WO | AV5: A | AW5: LWP
D6: 1 | E6: =Setting!E4 | F6: =IFERROR(VLOOKUP(E6,Setting!$E:$G,2,0),"") | G6: =IFERROR(VLOOKUP(E6,Setting!$E:$G,3,0),"") | AM6: =SUM(AN6:AW6) -> 0 | AN6: =COUNTIF($H6:$AL6,AN$5) -> 0 | AO6: =COUNTIF($H6:$AL6,AO$5) -> 0 | AP6: =COUNTIF($H6:$AL6,AP$5) -> 0 | AQ6: =COUNTIF($H6:$AL6,AQ$5) -> 0 | AR6: =COUNTIF($H6:$AL6,AR$5) -> 0 | AS6: =COUNTIF($H6:$AL6,AS$5) -> 0 | AT6: =COUNTIF($H6:$AL6,AT$5) -> 0 | AU6: =COUNTIF($H6:$AL6,AU$5) -> 0 | ... AW6: =COUNTIF($H6:$AL6,AW$5) -> 0
D7: 2 | E7: =Setting!E5 | F7: =IFERROR(VLOOKUP(E7,Setting!$E:$G,2,0),"") | G7: =IFERROR(VLOOKUP(E7,Setting!$E:$G,3,0),"") | AM7: =SUM(AN7:AW7) -> 0 | AN7: =COUNTIF($H7:$AL7,AN$5) -> 0 | AO7: =COUNTIF($H7:$AL7,AO$5) -> 0 | AP7: =COUNTIF($H7:$AL7,AP$5) -> 0 | AQ7: =COUNTIF($H7:$AL7,AQ$5) -> 0 | AR7: =COUNTIF($H7:$AL7,AR$5) -> 0 | AS7: =COUNTIF($H7:$AL7,AS$5) -> 0 | AT7: =COUNTIF($H7:$AL7,AT$5) -> 0 | AU7: =COUNTIF($H7:$AL7,AU$5) -> 0 | ... AW7: =COUNTIF($H7:$AL7,AW$5) -> 0
D8: 3 | E8: =Setting!E6 | F8: =IFERROR(VLOOKUP(E8,Setting!$E:$G,2,0),"") | G8: =IFERROR(VLOOKUP(E8,Setting!$E:$G,3,0),"") | AM8: =SUM(AN8:AW8) -> 0 | AN8: =COUNTIF($H8:$AL8,AN$5) -> 0 | AO8: =COUNTIF($H8:$AL8,AO$5) -> 0 | AP8: =COUNTIF($H8:$AL8,AP$5) -> 0 | AQ8: =COUNTIF($H8:$AL8,AQ$5) -> 0 | AR8: =COUNTIF($H8:$AL8,AR$5) -> 0 | AS8: =COUNTIF($H8:$AL8,AS$5) -> 0 | AT8: =COUNTIF($H8:$AL8,AT$5) -> 0 | AU8: =COUNTIF($H8:$AL8,AU$5) -> 0 | ... AW8: =COUNTIF($H8:$AL8,AW$5) -> 0
D9: 4 | E9: =Setting!E7 | F9: =IFERROR(VLOOKUP(E9,Setting!$E:$G,2,0),"") | G9: =IFERROR(VLOOKUP(E9,Setting!$E:$G,3,0),"") | AM9: =SUM(AN9:AW9) -> 0 | AN9: =COUNTIF($H9:$AL9,AN$5) -> 0 | AO9: =COUNTIF($H9:$AL9,AO$5) -> 0 | AP9: =COUNTIF($H9:$AL9,AP$5) -> 0 | AQ9: =COUNTIF($H9:$AL9,AQ$5) -> 0 | AR9: =COUNTIF($H9:$AL9,AR$5) -> 0 | AS9: =COUNTIF($H9:$AL9,AS$5) -> 0 | AT9: =COUNTIF($H9:$AL9,AT$5) -> 0 | AU9: =COUNTIF($H9:$AL9,AU$5) -> 0 | ... AW9: =COUNTIF($H9:$AL9,AW$5) -> 0
D10: 5 | E10: =Setting!E8 | F10: =IFERROR(VLOOKUP(E10,Setting!$E:$G,2,0),"") | G10: =IFERROR(VLOOKUP(E10,Setting!$E:$G,3,0),"") | AM10: =SUM(AN10:AW10) -> 0 | AN10: =COUNTIF($H10:$AL10,AN$5) -> 0 | AO10: =COUNTIF($H10:$AL10,AO$5) -> 0 | AP10: =COUNTIF($H10:$AL10,AP$5) -> 0 | AQ10: =COUNTIF($H10:$AL10,AQ$5) -> 0 | AR10: =COUNTIF($H10:$AL10,AR$5) -> 0 | AS10: =COUNTIF($H10:$AL10,AS$5) -> 0 | AT10: =COUNTIF($H10:$AL10,AT$5) -> 0 | AU10: =COUNTIF($H10:$AL10,AU$5) -> 0 | ... AW10: =COUNTIF($H10:$AL10,AW$5) -> 0
D11: 6 | E11: =Setting!E9 | F11: =IFERROR(VLOOKUP(E11,Setting!$E:$G,2,0),"") | G11: =IFERROR(VLOOKUP(E11,Setting!$E:$G,3,0),"") | AM11: =SUM(AN11:AW11) -> 0 | AN11: =COUNTIF($H11:$AL11,AN$5) -> 0 | AO11: =COUNTIF($H11:$AL11,AO$5) -> 0 | AP11: =COUNTIF($H11:$AL11,AP$5) -> 0 | AQ11: =COUNTIF($H11:$AL11,AQ$5) -> 0 | AR11: =COUNTIF($H11:$AL11,AR$5) -> 0 | AS11: =COUNTIF($H11:$AL11,AS$5) -> 0 | AT11: =COUNTIF($H11:$AL11,AT$5) -> 0 | AU11: =COUNTIF($H11:$AL11,AU$5) -> 0 | ... AW11: =COUNTIF($H11:$AL11,AW$5) -> 0
D12: 7 | E12: =Setting!E10 | F12: =IFERROR(VLOOKUP(E12,Setting!$E:$G,2,0),"") | G12: =IFERROR(VLOOKUP(E12,Setting!$E:$G,3,0),"") | AM12: =SUM(AN12:AW12) -> 0 | AN12: =COUNTIF($H12:$AL12,AN$5) -> 0 | AO12: =COUNTIF($H12:$AL12,AO$5) -> 0 | AP12: =COUNTIF($H12:$AL12,AP$5) -> 0 | AQ12: =COUNTIF($H12:$AL12,AQ$5) -> 0 | AR12: =COUNTIF($H12:$AL12,AR$5) -> 0 | AS12: =COUNTIF($H12:$AL12,AS$5) -> 0 | AT12: =COUNTIF($H12:$AL12,AT$5) -> 0 | AU12: =COUNTIF($H12:$AL12,AU$5) -> 0 | ... AW12: =COUNTIF($H12:$AL12,AW$5) -> 0
D13: 8 | E13: =Setting!E11 | F13: =IFERROR(VLOOKUP(E13,Setting!$E:$G,2,0),"") | G13: =IFERROR(VLOOKUP(E13,Setting!$E:$G,3,0),"") | AM13: =SUM(AN13:AW13) -> 0 | AN13: =COUNTIF($H13:$AL13,AN$5) -> 0 | AO13: =COUNTIF($H13:$AL13,AO$5) -> 0 | AP13: =COUNTIF($H13:$AL13,AP$5) -> 0 | AQ13: =COUNTIF($H13:$AL13,AQ$5) -> 0 | AR13: =COUNTIF($H13:$AL13,AR$5) -> 0 | AS13: =COUNTIF($H13:$AL13,AS$5) -> 0 | AT13: =COUNTIF($H13:$AL13,AT$5) -> 0 | AU13: =COUNTIF($H13:$AL13,AU$5) -> 0 | ... AW13: =COUNTIF($H13:$AL13,AW$5) -> 0
D14: 9 | E14: =Setting!E12 | F14: =IFERROR(VLOOKUP(E14,Setting!$E:$G,2,0),"") | G14: =IFERROR(VLOOKUP(E14,Setting!$E:$G,3,0),"") | AM14: =SUM(AN14:AW14) -> 0 | AN14: =COUNTIF($H14:$AL14,AN$5) -> 0 | AO14: =COUNTIF($H14:$AL14,AO$5) -> 0 | AP14: =COUNTIF($H14:$AL14,AP$5) -> 0 | AQ14: =COUNTIF($H14:$AL14,AQ$5) -> 0 | AR14: =COUNTIF($H14:$AL14,AR$5) -> 0 | AS14: =COUNTIF($H14:$AL14,AS$5) -> 0 | AT14: =COUNTIF($H14:$AL14,AT$5) -> 0 | AU14: =COUNTIF($H14:$AL14,AU$5) -> 0 | ... AW14: =COUNTIF($H14:$AL14,AW$5) -> 0
D15: 10 | E15: =Setting!E13 | F15: =IFERROR(VLOOKUP(E15,Setting!$E:$G,2,0),"") | G15: =IFERROR(VLOOKUP(E15,Setting!$E:$G,3,0),"") | AM15: =SUM(AN15:AW15) -> 0 | AN15: =COUNTIF($H15:$AL15,AN$5) -> 0 | AO15: =COUNTIF($H15:$AL15,AO$5) -> 0 | AP15: =COUNTIF($H15:$AL15,AP$5) -> 0 | AQ15: =COUNTIF($H15:$AL15,AQ$5) -> 0 | AR15: =COUNTIF($H15:$AL15,AR$5) -> 0 | AS15: =COUNTIF($H15:$AL15,AS$5) -> 0 | AT15: =COUNTIF($H15:$AL15,AT$5) -> 0 | AU15: =COUNTIF($H15:$AL15,AU$5) -> 0 | ... AW15: =COUNTIF($H15:$AL15,AW$5) -> 0
D16: 11 | E16: =Setting!E14 | F16: =IFERROR(VLOOKUP(E16,Setting!$E:$G,2,0),"") | G16: =IFERROR(VLOOKUP(E16,Setting!$E:$G,3,0),"") | AM16: =SUM(AN16:AW16) -> 0 | AN16: =COUNTIF($H16:$AL16,AN$5) -> 0 | AO16: =COUNTIF($H16:$AL16,AO$5) -> 0 | AP16: =COUNTIF($H16:$AL16,AP$5) -> 0 | AQ16: =COUNTIF($H16:$AL16,AQ$5) -> 0 | AR16: =COUNTIF($H16:$AL16,AR$5) -> 0 | AS16: =COUNTIF($H16:$AL16,AS$5) -> 0 | AT16: =COUNTIF($H16:$AL16,AT$5) -> 0 | AU16: =COUNTIF($H16:$AL16,AU$5) -> 0 | ... AW16: =COUNTIF($H16:$AL16,AW$5) -> 0
D17: 12 | E17: =Setting!E15 | F17: =IFERROR(VLOOKUP(E17,Setting!$E:$G,2,0),"") | G17: =IFERROR(VLOOKUP(E17,Setting!$E:$G,3,0),"") | AM17: =SUM(AN17:AW17) -> 0 | AN17: =COUNTIF($H17:$AL17,AN$5) -> 0 | AO17: =COUNTIF($H17:$AL17,AO$5) -> 0 | AP17: =COUNTIF($H17:$AL17,AP$5) -> 0 | AQ17: =COUNTIF($H17:$AL17,AQ$5) -> 0 | AR17: =COUNTIF($H17:$AL17,AR$5) -> 0 | AS17: =COUNTIF($H17:$AL17,AS$5) -> 0 | AT17: =COUNTIF($H17:$AL17,AT$5) -> 0 | AU17: =COUNTIF($H17:$AL17,AU$5) -> 0 | ... AW17: =COUNTIF($H17:$AL17,AW$5) -> 0
... D25: 20 | E25: =Setting!E23 | F25: =IFERROR(VLOOKUP(E25,Setting!$E:$G,2,0),"") | G25: =IFERROR(VLOOKUP(E25,Setting!$E:$G,3,0),"") | AM25: =SUM(AN25:AW25) -> 0 | AN25: =COUNTIF($H25:$AL25,AN$5) -> 0 | AO25: =COUNTIF($H25:$AL25,AO$5) -> 0 | AP25: =COUNTIF($H25:$AL25,AP$5) -> 0 | AQ25: =COUNTIF($H25:$AL25,AQ$5) -> 0 | AR25: =COUNTIF($H25:$AL25,AR$5) -> 0 | AS25: =COUNTIF($H25:$AL25,AS$5) -> 0 | AT25: =COUNTIF($H25:$AL25,AT$5) -> 0 | AU25: =COUNTIF($H25:$AL25,AU$5) -> 0 | ... AW25: =COUNTIF($H25:$AL25,AW$5) -> 0

Sheet April
I2: Monthly Leave Tracker
F3: April | G3: 2023 | H3: =IFERROR(VLOOKUP(H4,Holidays,2,0),"") | I3: =IFERROR(VLOOKUP(I4,Holidays,2,0),"") | J3: =IFERROR(VLOOKUP(J4,Holidays,2,0),"") | K3: =IFERROR(VLOOKUP(K4,Holidays,2,0),"") | L3: =IFERROR(VLOOKUP(L4,Holidays,2,0),"") | M3: =IFERROR(VLOOKUP(M4,Holidays,2,0),"") | N3: =IFERROR(VLOOKUP(N4,Holidays,2,0),"") | O3: =IFERROR(VLOOKUP(O4,Holidays,2,0),"") | ... AL3: =IFERROR(VLOOKUP(AL4,Holidays,2,0),"") | AM3: Summary
D4: SL. No. | E4: Emp. Code | F4: Employee Name | G4: Designation | H4: =DATEVALUE("1"&F3&G3) -> 45017 | I4: =IF(H$4<EOMONTH($H$4,0),H4+1,"EOM") -> 45018 | J4: =IF(I$4<EOMONTH($H$4,0),I4+1,"EOM") -> 45019 | K4: =IF(J$4<EOMONTH($H$4,0),J4+1,"EOM") -> 45020 | L4: =IF(K$4<EOMONTH($H$4,0),K4+1,"EOM") -> 45021 | M4: =IF(L$4<EOMONTH($H$4,0),L4+1,"EOM") -> 45022 | N4: =IF(M$4<EOMONTH($H$4,0),M4+1,"EOM") -> 45023 | O4: =IF(N$4<EOMONTH($H$4,0),N4+1,"EOM") -> 45024 | P4: =IF(O$4<EOMONTH($H$4,0),O4+1,"EOM") -> 45025 | ... AL4: =IF(AK$4<EOMONTH($H$4,0),AK4+1,"EOM") -> EOM | AM4: Total Leaves | AN4: Casual Leave | AO4: Privilaged Leave | AP4: Sick Leave | AQ4: Maternity or Paternity | AR4: Half Day | AS4: Work from Home | AT4: Holidays | AU4: Week Offs | AV4: Total Absent / No Show | AW4: Leave Without Pay
H5: =TEXT(H4,"DDD") -> Sat | I5: =TEXT(I4,"DDD") -> Sun | J5: =TEXT(J4,"DDD") -> Mon | K5: =TEXT(K4,"DDD") -> Tue | L5: =TEXT(L4,"DDD") -> Wed | M5: =TEXT(M4,"DDD") -> Thu | N5: =TEXT(N4,"DDD") -> Fri | O5: =TEXT(O4,"DDD") -> Sat | ... AL5: =TEXT(AL4,"DDD") -> EOM | AN5: CL | AO5: PL | AP5: SL | AQ5: ML | AR5: HD | AS5: WH | AT5: H | AU5: WO | AV5: A | AW5: LWP
D6: 1 | E6: =Setting!E4 | F6: =IFERROR(VLOOKUP(E6,Setting!$E:$G,2,0),"") | G6: =IFERROR(VLOOKUP(E6,Setting!$E:$G,3,0),"") | AM6: =SUM(AN6:AW6) -> 0 | AN6: =COUNTIF($H6:$AL6,AN$5) -> 0 | AO6: =COUNTIF($H6:$AL6,AO$5) -> 0 | AP6: =COUNTIF($H6:$AL6,AP$5) -> 0 | AQ6: =COUNTIF($H6:$AL6,AQ$5) -> 0 | AR6: =COUNTIF($H6:$AL6,AR$5) -> 0 | AS6: =COUNTIF($H6:$AL6,AS$5) -> 0 | AT6: =COUNTIF($H6:$AL6,AT$5) -> 0 | AU6: =COUNTIF($H6:$AL6,AU$5) -> 0 | ... AW6: =COUNTIF($H6:$AL6,AW$5) -> 0
D7: 2 | E7: =Setting!E5 | F7: =IFERROR(VLOOKUP(E7,Setting!$E:$G,2,0),"") | G7: =IFERROR(VLOOKUP(E7,Setting!$E:$G,3,0),"") | AM7: =SUM(AN7:AW7) -> 0 | AN7: =COUNTIF($H7:$AL7,AN$5) -> 0 | AO7: =COUNTIF($H7:$AL7,AO$5) -> 0 | AP7: =COUNTIF($H7:$AL7,AP$5) -> 0 | AQ7: =COUNTIF($H7:$AL7,AQ$5) -> 0 | AR7: =COUNTIF($H7:$AL7,AR$5) -> 0 | AS7: =COUNTIF($H7:$AL7,AS$5) -> 0 | AT7: =COUNTIF($H7:$AL7,AT$5) -> 0 | AU7: =COUNTIF($H7:$AL7,AU$5) -> 0 | ... AW7: =COUNTIF($H7:$AL7,AW$5) -> 0
D8: 3 | E8: =Setting!E6 | F8: =IFERROR(VLOOKUP(E8,Setting!$E:$G,2,0),"") | G8: =IFERROR(VLOOKUP(E8,Setting!$E:$G,3,0),"") | AM8: =SUM(AN8:AW8) -> 0 | AN8: =COUNTIF($H8:$AL8,AN$5) -> 0 | AO8: =COUNTIF($H8:$AL8,AO$5) -> 0 | AP8: =COUNTIF($H8:$AL8,AP$5) -> 0 | AQ8: =COUNTIF($H8:$AL8,AQ$5) -> 0 | AR8: =COUNTIF($H8:$AL8,AR$5) -> 0 | AS8: =COUNTIF($H8:$AL8,AS$5) -> 0 | AT8: =COUNTIF($H8:$AL8,AT$5) -> 0 | AU8: =COUNTIF($H8:$AL8,AU$5) -> 0 | ... AW8: =COUNTIF($H8:$AL8,AW$5) -> 0
D9: 4 | E9: =Setting!E7 | F9: =IFERROR(VLOOKUP(E9,Setting!$E:$G,2,0),"") | G9: =IFERROR(VLOOKUP(E9,Setting!$E:$G,3,0),"") | AM9: =SUM(AN9:AW9) -> 0 | AN9: =COUNTIF($H9:$AL9,AN$5) -> 0 | AO9: =COUNTIF($H9:$AL9,AO$5) -> 0 | AP9: =COUNTIF($H9:$AL9,AP$5) -> 0 | AQ9: =COUNTIF($H9:$AL9,AQ$5) -> 0 | AR9: =COUNTIF($H9:$AL9,AR$5) -> 0 | AS9: =COUNTIF($H9:$AL9,AS$5) -> 0 | AT9: =COUNTIF($H9:$AL9,AT$5) -> 0 | AU9: =COUNTIF($H9:$AL9,AU$5) -> 0 | ... AW9: =COUNTIF($H9:$AL9,AW$5) -> 0
D10: 5 | E10: =Setting!E8 | G10: =IFERROR(VLOOKUP(E10,Setting!$E:$G,3,0),"") | AM10: =SUM(AN10:AW10) -> 0 | AN10: =COUNTIF($H10:$AL10,AN$5) -> 0 | AO10: =COUNTIF($H10:$AL10,AO$5) -> 0 | AP10: =COUNTIF($H10:$AL10,AP$5) -> 0 | AQ10: =COUNTIF($H10:$AL10,AQ$5) -> 0 | AR10: =COUNTIF($H10:$AL10,AR$5) -> 0 | AS10: =COUNTIF($H10:$AL10,AS$5) -> 0 | AT10: =COUNTIF($H10:$AL10,AT$5) -> 0 | AU10: =COUNTIF($H10:$AL10,AU$5) -> 0 | ... AW10: =COUNTIF($H10:$AL10,AW$5) -> 0
D11: 6 | E11: =Setting!E9 | F11: =IFERROR(VLOOKUP(E11,Setting!$E:$G,2,0),"") | G11: =IFERROR(VLOOKUP(E11,Setting!$E:$G,3,0),"") | AM11: =SUM(AN11:AW11) -> 0 | AN11: =COUNTIF($H11:$AL11,AN$5) -> 0 | AO11: =COUNTIF($H11:$AL11,AO$5) -> 0 | AP11: =COUNTIF($H11:$AL11,AP$5) -> 0 | AQ11: =COUNTIF($H11:$AL11,AQ$5) -> 0 | AR11: =COUNTIF($H11:$AL11,AR$5) -> 0 | AS11: =COUNTIF($H11:$AL11,AS$5) -> 0 | AT11: =COUNTIF($H11:$AL11,AT$5) -> 0 | AU11: =COUNTIF($H11:$AL11,AU$5) -> 0 | ... AW11: =COUNTIF($H11:$AL11,AW$5) -> 0
D12: 7 | E12: =Setting!E10 | F12: =IFERROR(VLOOKUP(E12,Setting!$E:$G,2,0),"") | G12: =IFERROR(VLOOKUP(E12,Setting!$E:$G,3,0),"") | AM12: =SUM(AN12:AW12) -> 0 | AN12: =COUNTIF($H12:$AL12,AN$5) -> 0 | AO12: =COUNTIF($H12:$AL12,AO$5) -> 0 | AP12: =COUNTIF($H12:$AL12,AP$5) -> 0 | AQ12: =COUNTIF($H12:$AL12,AQ$5) -> 0 | AR12: =COUNTIF($H12:$AL12,AR$5) -> 0 | AS12: =COUNTIF($H12:$AL12,AS$5) -> 0 | AT12: =COUNTIF($H12:$AL12,AT$5) -> 0 | AU12: =COUNTIF($H12:$AL12,AU$5) -> 0 | ... AW12: =COUNTIF($H12:$AL12,AW$5) -> 0
D13: 8 | E13: =Setting!E11 | F13: =IFERROR(VLOOKUP(E13,Setting!$E:$G,2,0),"") | G13: =IFERROR(VLOOKUP(E13,Setting!$E:$G,3,0),"") | AM13: =SUM(AN13:AW13) -> 0 | AN13: =COUNTIF($H13:$AL13,AN$5) -> 0 | AO13: =COUNTIF($H13:$AL13,AO$5) -> 0 | AP13: =COUNTIF($H13:$AL13,AP$5) -> 0 | AQ13: =COUNTIF($H13:$AL13,AQ$5) -> 0 | AR13: =COUNTIF($H13:$AL13,AR$5) -> 0 | AS13: =COUNTIF($H13:$AL13,AS$5) -> 0 | AT13: =COUNTIF($H13:$AL13,AT$5) -> 0 | AU13: =COUNTIF($H13:$AL13,AU$5) -> 0 | ... AW13: =COUNTIF($H13:$AL13,AW$5) -> 0
D14: 9 | E14: =Setting!E12 | F14: =IFERROR(VLOOKUP(E14,Setting!$E:$G,2,0),"") | G14: =IFERROR(VLOOKUP(E14,Setting!$E:$G,3,0),"") | AM14: =SUM(AN14:AW14) -> 0 | AN14: =COUNTIF($H14:$AL14,AN$5) -> 0 | AO14: =COUNTIF($H14:$AL14,AO$5) -> 0 | AP14: =COUNTIF($H14:$AL14,AP$5) -> 0 | AQ14: =COUNTIF($H14:$AL14,AQ$5) -> 0 | AR14: =COUNTIF($H14:$AL14,AR$5) -> 0 | AS14: =COUNTIF($H14:$AL14,AS$5) -> 0 | AT14: =COUNTIF($H14:$AL14,AT$5) -> 0 | AU14: =COUNTIF($H14:$AL14,AU$5) -> 0 | ... AW14: =COUNTIF($H14:$AL14,AW$5) -> 0
D15: 10 | E15: =Setting!E13 | F15: =IFERROR(VLOOKUP(E15,Setting!$E:$G,2,0),"") | G15: =IFERROR(VLOOKUP(E15,Setting!$E:$G,3,0),"") | AM15: =SUM(AN15:AW15) -> 0 | AN15: =COUNTIF($H15:$AL15,AN$5) -> 0 | AO15: =COUNTIF($H15:$AL15,AO$5) -> 0 | AP15: =COUNTIF($H15:$AL15,AP$5) -> 0 | AQ15: =COUNTIF($H15:$AL15,AQ$5) -> 0 | AR15: =COUNTIF($H15:$AL15,AR$5) -> 0 | AS15: =COUNTIF($H15:$AL15,AS$5) -> 0 | AT15: =COUNTIF($H15:$AL15,AT$5) -> 0 | AU15: =COUNTIF($H15:$AL15,AU$5) -> 0 | ... AW15: =COUNTIF($H15:$AL15,AW$5) -> 0
D16: 11 | E16: =Setting!E14 | F16: =IFERROR(VLOOKUP(E16,Setting!$E:$G,2,0),"") | G16: =IFERROR(VLOOKUP(E16,Setting!$E:$G,3,0),"") | AM16: =SUM(AN16:AW16) -> 0 | AN16: =COUNTIF($H16:$AL16,AN$5) -> 0 | AO16: =COUNTIF($H16:$AL16,AO$5) -> 0 | AP16: =COUNTIF($H16:$AL16,AP$5) -> 0 | AQ16: =COUNTIF($H16:$AL16,AQ$5) -> 0 | AR16: =COUNTIF($H16:$AL16,AR$5) -> 0 | AS16: =COUNTIF($H16:$AL16,AS$5) -> 0 | AT16: =COUNTIF($H16:$AL16,AT$5) -> 0 | AU16: =COUNTIF($H16:$AL16,AU$5) -> 0 | ... AW16: =COUNTIF($H16:$AL16,AW$5) -> 0
D17: 12 | E17: =Setting!E15 | F17: =IFERROR(VLOOKUP(E17,Setting!$E:$G,2,0),"") | G17: =IFERROR(VLOOKUP(E17,Setting!$E:$G,3,0),"") | AM17: =SUM(AN17:AW17) -> 0 | AN17: =COUNTIF($H17:$AL17,AN$5) -> 0 | AO17: =COUNTIF($H17:$AL17,AO$5) -> 0 | AP17: =COUNTIF($H17:$AL17,AP$5) -> 0 | AQ17: =COUNTIF($H17:$AL17,AQ$5) -> 0 | AR17: =COUNTIF($H17:$AL17,AR$5) -> 0 | AS17: =COUNTIF($H17:$AL17,AS$5) -> 0 | AT17: =COUNTIF($H17:$AL17,AT$5) -> 0 | AU17: =COUNTIF($H17:$AL17,AU$5) -> 0 | ... AW17: =COUNTIF($H17:$AL17,AW$5) -> 0
D18: 13 | E18: =Setting!E16 | F18: =IFERROR(VLOOKUP(E18,Setting!$E:$G,2,0),"") | G18: =IFERROR(VLOOKUP(E18,Setting!$E:$G,3,0),"") | AM18: =SUM(AN18:AW18) -> 0 | AN18: =COUNTIF($H18:$AL18,AN$5) -> 0 | AO18: =COUNTIF($H18:$AL18,AO$5) -> 0 | AP18: =COUNTIF($H18:$AL18,AP$5) -> 0 | AQ18: =COUNTIF($H18:$AL18,AQ$5) -> 0 | AR18: =COUNTIF($H18:$AL18,AR$5) -> 0 | AS18: =COUNTIF($H18:$AL18,AS$5) -> 0 | AT18: =COUNTIF($H18:$AL18,AT$5) -> 0 | AU18: =COUNTIF($H18:$AL18,AU$5) -> 0 | ... AW18: =COUNTIF($H18:$AL18,AW$5) -> 0
D19: 14 | E19: =Setting!E17 | F19: =IFERROR(VLOOKUP(E19,Setting!$E:$G,2,0),"") | G19: =IFERROR(VLOOKUP(E19,Setting!$E:$G,3,0),"") | AM19: =SUM(AN19:AW19) -> 0 | AN19: =COUNTIF($H19:$AL19,AN$5) -> 0 | AO19: =COUNTIF($H19:$AL19,AO$5) -> 0 | AP19: =COUNTIF($H19:$AL19,AP$5) -> 0 | AQ19: =COUNTIF($H19:$AL19,AQ$5) -> 0 | AR19: =COUNTIF($H19:$AL19,AR$5) -> 0 | AS19: =COUNTIF($H19:$AL19,AS$5) -> 0 | AT19: =COUNTIF($H19:$AL19,AT$5) -> 0 | AU19: =COUNTIF($H19:$AL19,AU$5) -> 0 | ... AW19: =COUNTIF($H19:$AL19,AW$5) -> 0
D20: 15 | E20: =Setting!E18 | F20: =IFERROR(VLOOKUP(E20,Setting!$E:$G,2,0),"") | G20: =IFERROR(VLOOKUP(E20,Setting!$E:$G,3,0),"") | AM20: =SUM(AN20:AW20) -> 0 | AN20: =COUNTIF($H20:$AL20,AN$5) -> 0 | AO20: =COUNTIF($H20:$AL20,AO$5) -> 0 | AP20: =COUNTIF($H20:$AL20,AP$5) -> 0 | AQ20: =COUNTIF($H20:$AL20,AQ$5) -> 0 | AR20: =COUNTIF($H20:$AL20,AR$5) -> 0 | AS20: =COUNTIF($H20:$AL20,AS$5) -> 0 | AT20: =COUNTIF($H20:$AL20,AT$5) -> 0 | AU20: =COUNTIF($H20:$AL20,AU$5) -> 0 | ... AW20: =COUNTIF($H20:$AL20,AW$5) -> 0
D21: 16 | E21: =Setting!E19 | F21: =IFERROR(VLOOKUP(E21,Setting!$E:$G,2,0),"") | G21: =IFERROR(VLOOKUP(E21,Setting!$E:$G,3,0),"") | AM21: =SUM(AN21:AW21) -> 0 | AN21: =COUNTIF($H21:$AL21,AN$5) -> 0 | AO21: =COUNTIF($H21:$AL21,AO$5) -> 0 | AP21: =COUNTIF($H21:$AL21,AP$5) -> 0 | AQ21: =COUNTIF($H21:$AL21,AQ$5) -> 0 | AR21: =COUNTIF($H21:$AL21,AR$5) -> 0 | AS21: =COUNTIF($H21:$AL21,AS$5) -> 0 | AT21: =COUNTIF($H21:$AL21,AT$5) -> 0 | AU21: =COUNTIF($H21:$AL21,AU$5) -> 0 | ... AW21: =COUNTIF($H21:$AL21,AW$5) -> 0
D22: 17 | E22: =Setting!E20 | F22: =IFERROR(VLOOKUP(E22,Setting!$E:$G,2,0),"") | G22: =IFERROR(VLOOKUP(E22,Setting!$E:$G,3,0),"") | AM22: =SUM(AN22:AW22) -> 0 | AN22: =COUNTIF($H22:$AL22,AN$5) -> 0 | AO22: =COUNTIF($H22:$AL22,AO$5) -> 0 | AP22: =COUNTIF($H22:$AL22,AP$5) -> 0 | AQ22: =COUNTIF($H22:$AL22,AQ$5) -> 0 | AR22: =COUNTIF($H22:$AL22,AR$5) -> 0 | AS22: =COUNTIF($H22:$AL22,AS$5) -> 0 | AT22: =COUNTIF($H22:$AL22,AT$5) -> 0 | AU22: =COUNTIF($H22:$AL22,AU$5) -> 0 | ... AW22: =COUNTIF($H22:$AL22,AW$5) -> 0
... D25: 20 | E25: =Setting!E23 | F25: =IFERROR(VLOOKUP(E25,Setting!$E:$G,2,0),"") | G25: =IFERROR(VLOOKUP(E25,Setting!$E:$G,3,0),"") | AM25: =SUM(AN25:AW25) -> 0 | AN25: =COUNTIF($H25:$AL25,AN$5) -> 0 | AO25: =COUNTIF($H25:$AL25,AO$5) -> 0 | AP25: =COUNTIF($H25:$AL25,AP$5) -> 0 | AQ25: =COUNTIF($H25:$AL25,AQ$5) -> 0 | AR25: =COUNTIF($H25:$AL25,AR$5) -> 0 | AS25: =COUNTIF($H25:$AL25,AS$5) -> 0 | AT25: =COUNTIF($H25:$AL25,AT$5) -> 0 | AU25: =COUNTIF($H25:$AL25,AU$5) -> 0 | ... AW25: =COUNTIF($H25:$AL25,AW$5) -> 0

Sheet May
I2: Monthly Leave Tracker
F3: May | G3: 2023 | H3: =IFERROR(VLOOKUP(H4,Holidays,2,0),"") | I3: =IFERROR(VLOOKUP(I4,Holidays,2,0),"") | J3: =IFERROR(VLOOKUP(J4,Holidays,2,0),"") | K3: =IFERROR(VLOOKUP(K4,Holidays,2,0),"") | L3: =IFERROR(VLOOKUP(L4,Holidays,2,0),"") | M3: =IFERROR(VLOOKUP(M4,Holidays,2,0),"") | N3: =IFERROR(VLOOKUP(N4,Holidays,2,0),"") | O3: =IFERROR(VLOOKUP(O4,Holidays,2,0),"") | ... AL3: =IFERROR(VLOOKUP(AL4,Holidays,2,0),"") | AM3: Summary
D4: SL. No. | E4: Emp. Code | F4: Employee Name | G4: Designation | H4: =DATEVALUE("1"&F3&G3) -> 45047 | I4: =IF(H$4<EOMONTH($H$4,0),H4+1,"EOM") -> 45048 | J4: =IF(I$4<EOMONTH($H$4,0),I4+1,"EOM") -> 45049 | K4: =IF(J$4<EOMONTH($H$4,0),J4+1,"EOM") -> 45050 | L4: =IF(K$4<EOMONTH($H$4,0),K4+1,"EOM") -> 45051 | M4: =IF(L$4<EOMONTH($H$4,0),L4+1,"EOM") -> 45052 | N4: =IF(M$4<EOMONTH($H$4,0),M4+1,"EOM") -> 45053 | O4: =IF(N$4<EOMONTH($H$4,0),N4+1,"EOM") -> 45054 | P4: =IF(O$4<EOMONTH($H$4,0),O4+1,"EOM") -> 45055 | ... AL4: =IF(AK$4<EOMONTH($H$4,0),AK4+1,"EOM") -> 45077 | AM4: Total Leaves | AN4: Casual Leave | AO4: Privilaged Leave | AP4: Sick Leave | AQ4: Maternity or Paternity | AR4: Half Day | AS4: Work from Home | AT4: Holidays | AU4: Week Offs | AV4: Total Absent / No Show | AW4: Leave Without Pay
H5: =TEXT(H4,"DDD") -> Mon | I5: =TEXT(I4,"DDD") -> Tue | J5: =TEXT(J4,"DDD") -> Wed | K5: =TEXT(K4,"DDD") -> Thu | L5: =TEXT(L4,"DDD") -> Fri | M5: =TEXT(M4,"DDD") -> Sat | N5: =TEXT(N4,"DDD") -> Sun | O5: =TEXT(O4,"DDD") -> Mon | ... AL5: =TEXT(AL4,"DDD") -> Wed | AN5: CL | AO5: PL | AP5: SL | AQ5: ML | AR5: HD | AS5: WH | AT5: H | AU5: WO | AV5: A | AW5: LWP
D6: 1 | E6: =Setting!E4 | F6: =IFERROR(VLOOKUP(E6,Setting!$E:$G,2,0),"") | G6: =IFERROR(VLOOKUP(E6,Setting!$E:$G,3,0),"") | AM6: =SUM(AN6:AW6) -> 0 | AN6: =COUNTIF($H6:$AL6,AN$5) -> 0 | AO6: =COUNTIF($H6:$AL6,AO$5) -> 0 | AP6: =COUNTIF($H6:$AL6,AP$5) -> 0 | AQ6: =COUNTIF($H6:$AL6,AQ$5) -> 0 | AR6: =COUNTIF($H6:$AL6,AR$5) -> 0 | AS6: =COUNTIF($H6:$AL6,AS$5) -> 0 | AT6: =COUNTIF($H6:$AL6,AT$5) -> 0 | AU6: =COUNTIF($H6:$AL6,AU$5) -> 0 | ... AW6: =COUNTIF($H6:$AL6,AW$5) -> 0
D7: 2 | E7: =Setting!E5 | F7: =IFERROR(VLOOKUP(E7,Setting!$E:$G,2,0),"") | G7: =IFERROR(VLOOKUP(E7,Setting!$E:$G,3,0),"") | AM7: =SUM(AN7:AW7) -> 0 | AN7: =COUNTIF($H7:$AL7,AN$5) -> 0 | AO7: =COUNTIF($H7:$AL7,AO$5) -> 0 | AP7: =COUNTIF($H7:$AL7,AP$5) -> 0 | AQ7: =COUNTIF($H7:$AL7,AQ$5) -> 0 | AR7: =COUNTIF($H7:$AL7,AR$5) -> 0 | AS7: =COUNTIF($H7:$AL7,AS$5) -> 0 | AT7: =COUNTIF($H7:$AL7,AT$5) -> 0 | AU7: =COUNTIF($H7:$AL7,AU$5) -> 0 | ... AW7: =COUNTIF($H7:$AL7,AW$5) -> 0
D8: 3 | E8: =Setting!E6 | F8: =IFERROR(VLOOKUP(E8,Setting!$E:$G,2,0),"") | G8: =IFERROR(VLOOKUP(E8,Setting!$E:$G,3,0),"") | AM8: =SUM(AN8:AW8) -> 0 | AN8: =COUNTIF($H8:$AL8,AN$5) -> 0 | AO8: =COUNTIF($H8:$AL8,AO$5) -> 0 | AP8: =COUNTIF($H8:$AL8,AP$5) -> 0 | AQ8: =COUNTIF($H8:$AL8,AQ$5) -> 0 | AR8: =COUNTIF($H8:$AL8,AR$5) -> 0 | AS8: =COUNTIF($H8:$AL8,AS$5) -> 0 | AT8: =COUNTIF($H8:$AL8,AT$5) -> 0 | AU8: =COUNTIF($H8:$AL8,AU$5) -> 0 | ... AW8: =COUNTIF($H8:$AL8,AW$5) -> 0
D9: 4 | E9: =Setting!E7 | F9: =IFERROR(VLOOKUP(E9,Setting!$E:$G,2,0),"") | G9: =IFERROR(VLOOKUP(E9,Setting!$E:$G,3,0),"") | AM9: =SUM(AN9:AW9) -> 0 | AN9: =COUNTIF($H9:$AL9,AN$5) -> 0 | AO9: =COUNTIF($H9:$AL9,AO$5) -> 0 | AP9: =COUNTIF($H9:$AL9,AP$5) -> 0 | AQ9: =COUNTIF($H9:$AL9,AQ$5) -> 0 | AR9: =COUNTIF($H9:$AL9,AR$5) -> 0 | AS9: =COUNTIF($H9:$AL9,AS$5) -> 0 | AT9: =COUNTIF($H9:$AL9,AT$5) -> 0 | AU9: =COUNTIF($H9:$AL9,AU$5) -> 0 | ... AW9: =COUNTIF($H9:$AL9,AW$5) -> 0
D10: 5 | E10: =Setting!E8 | F10: =IFERROR(VLOOKUP(E10,Setting!$E:$G,2,0),"") | G10: =IFERROR(VLOOKUP(E10,Setting!$E:$G,3,0),"") | AM10: =SUM(AN10:AW10) -> 0 | AN10: =COUNTIF($H10:$AL10,AN$5) -> 0 | AO10: =COUNTIF($H10:$AL10,AO$5) -> 0 | AP10: =COUNTIF($H10:$AL10,AP$5) -> 0 | AQ10: =COUNTIF($H10:$AL10,AQ$5) -> 0 | AR10: =COUNTIF($H10:$AL10,AR$5) -> 0 | AS10: =COUNTIF($H10:$AL10,AS$5) -> 0 | AT10: =COUNTIF($H10:$AL10,AT$5) -> 0 | AU10: =COUNTIF($H10:$AL10,AU$5) -> 0 | ... AW10: =COUNTIF($H10:$AL10,AW$5) -> 0
D11: 6 | E11: =Setting!E9 | F11: =IFERROR(VLOOKUP(E11,Setting!$E:$G,2,0),"") | G11: =IFERROR(VLOOKUP(E11,Setting!$E:$G,3,0),"") | AM11: =SUM(AN11:AW11) -> 0 | AN11: =COUNTIF($H11:$AL11,AN$5) -> 0 | AO11: =COUNTIF($H11:$AL11,AO$5) -> 0 | AP11: =COUNTIF($H11:$AL11,AP$5) -> 0 | AQ11: =COUNTIF($H11:$AL11,AQ$5) -> 0 | AR11: =COUNTIF($H11:$AL11,AR$5) -> 0 | AS11: =COUNTIF($H11:$AL11,AS$5) -> 0 | AT11: =COUNTIF($H11:$AL11,AT$5) -> 0 | AU11: =COUNTIF($H11:$AL11,AU$5) -> 0 | ... AW11: =COUNTIF($H11:$AL11,AW$5) -> 0
D12: 7 | E12: =Setting!E10 | F12: =IFERROR(VLOOKUP(E12,Setting!$E:$G,2,0),"") | G12: =IFERROR(VLOOKUP(E12,Setting!$E:$G,3,0),"") | AM12: =SUM(AN12:AW12) -> 0 | AN12: =COUNTIF($H12:$AL12,AN$5) -> 0 | AO12: =COUNTIF($H12:$AL12,AO$5) -> 0 | AP12: =COUNTIF($H12:$AL12,AP$5) -> 0 | AQ12: =COUNTIF($H12:$AL12,AQ$5) -> 0 | AR12: =COUNTIF($H12:$AL12,AR$5) -> 0 | AS12: =COUNTIF($H12:$AL12,AS$5) -> 0 | AT12: =COUNTIF($H12:$AL12,AT$5) -> 0 | AU12: =COUNTIF($H12:$AL12,AU$5) -> 0 | ... AW12: =COUNTIF($H12:$AL12,AW$5) -> 0
D13: 8 | E13: =Setting!E11 | F13: =IFERROR(VLOOKUP(E13,Setting!$E:$G,2,0),"") | G13: =IFERROR(VLOOKUP(E13,Setting!$E:$G,3,0),"") | AM13: =SUM(AN13:AW13) -> 0 | AN13: =COUNTIF($H13:$AL13,AN$5) -> 0 | AO13: =COUNTIF($H13:$AL13,AO$5) -> 0 | AP13: =COUNTIF($H13:$AL13,AP$5) -> 0 | AQ13: =COUNTIF($H13:$AL13,AQ$5) -> 0 | AR13: =COUNTIF($H13:$AL13,AR$5) -> 0 | AS13: =COUNTIF($H13:$AL13,AS$5) -> 0 | AT13: =COUNTIF($H13:$AL13,AT$5) -> 0 | AU13: =COUNTIF($H13:$AL13,AU$5) -> 0 | ... AW13: =COUNTIF($H13:$AL13,AW$5) -> 0
D14: 9 | E14: =Setting!E12 | F14: =IFERROR(VLOOKUP(E14,Setting!$E:$G,2,0),"") | G14: =IFERROR(VLOOKUP(E14,Setting!$E:$G,3,0),"") | AM14: =SUM(AN14:AW14) -> 0 | AN14: =COUNTIF($H14:$AL14,AN$5) -> 0 | AO14: =COUNTIF($H14:$AL14,AO$5) -> 0 | AP14: =COUNTIF($H14:$AL14,AP$5) -> 0 | AQ14: =COUNTIF($H14:$AL14,AQ$5) -> 0 | AR14: =COUNTIF($H14:$AL14,AR$5) -> 0 | AS14: =COUNTIF($H14:$AL14,AS$5) -> 0 | AT14: =COUNTIF($H14:$AL14,AT$5) -> 0 | AU14: =COUNTIF($H14:$AL14,AU$5) -> 0 | ... AW14: =COUNTIF($H14:$AL14,AW$5) -> 0
D15: 10 | E15: =Setting!E13 | F15: =IFERROR(VLOOKUP(E15,Setting!$E:$G,2,0),"") | G15: =IFERROR(VLOOKUP(E15,Setting!$E:$G,3,0),"") | AM15: =SUM(AN15:AW15) -> 0 | AN15: =COUNTIF($H15:$AL15,AN$5) -> 0 | AO15: =COUNTIF($H15:$AL15,AO$5) -> 0 | AP15: =COUNTIF($H15:$AL15,AP$5) -> 0 | AQ15: =COUNTIF($H15:$AL15,AQ$5) -> 0 | AR15: =COUNTIF($H15:$AL15,AR$5) -> 0 | AS15: =COUNTIF($H15:$AL15,AS$5) -> 0 | AT15: =COUNTIF($H15:$AL15,AT$5) -> 0 | AU15: =COUNTIF($H15:$AL15,AU$5) -> 0 | ... AW15: =COUNTIF($H15:$AL15,AW$5) -> 0
D16: 11 | E16: =Setting!E14 | F16: =IFERROR(VLOOKUP(E16,Setting!$E:$G,2,0),"") | G16: =IFERROR(VLOOKUP(E16,Setting!$E:$G,3,0),"") | AM16: =SUM(AN16:AW16) -> 0 | AN16: =COUNTIF($H16:$AL16,AN$5) -> 0 | AO16: =COUNTIF($H16:$AL16,AO$5) -> 0 | AP16: =COUNTIF($H16:$AL16,AP$5) -> 0 | AQ16: =COUNTIF($H16:$AL16,AQ$5) -> 0 | AR16: =COUNTIF($H16:$AL16,AR$5) -> 0 | AS16: =COUNTIF($H16:$AL16,AS$5) -> 0 | AT16: =COUNTIF($H16:$AL16,AT$5) -> 0 | AU16: =COUNTIF($H16:$AL16,AU$5) -> 0 | ... AW16: =COUNTIF($H16:$AL16,AW$5) -> 0
D17: 12 | E17: =Setting!E15 | F17: =IFERROR(VLOOKUP(E17,Setting!$E:$G,2,0),"") | G17: =IFERROR(VLOOKUP(E17,Setting!$E:$G,3,0),"") | AM17: =SUM(AN17:AW17) -> 0 | AN17: =COUNTIF($H17:$AL17,AN$5) -> 0 | AO17: =COUNTIF($H17:$AL17,AO$5) -> 0 | AP17: =COUNTIF($H17:$AL17,AP$5) -> 0 | AQ17: =COUNTIF($H17:$AL17,AQ$5) -> 0 | AR17: =COUNTIF($H17:$AL17,AR$5) -> 0 | AS17: =COUNTIF($H17:$AL17,AS$5) -> 0 | AT17: =COUNTIF($H17:$AL17,AT$5) -> 0 | AU17: =COUNTIF($H17:$AL17,AU$5) -> 0 | ... AW17: =COUNTIF($H17:$AL17,AW$5) -> 0
... D25: 20 | E25: =Setting!E23 | F25: =IFERROR(VLOOKUP(E25,Setting!$E:$G,2,0),"") | G25: =IFERROR(VLOOKUP(E25,Setting!$E:$G,3,0),"") | AM25: =SUM(AN25:AW25) -> 0 | AN25: =COUNTIF($H25:$AL25,AN$5) -> 0 | AO25: =COUNTIF($H25:$AL25,AO$5) -> 0 | AP25: =COUNTIF($H25:$AL25,AP$5) -> 0 | AQ25: =COUNTIF($H25:$AL25,AQ$5) -> 0 | AR25: =COUNTIF($H25:$AL25,AR$5) -> 0 | AS25: =COUNTIF($H25:$AL25,AS$5) -> 0 | AT25: =COUNTIF($H25:$AL25,AT$5) -> 0 | AU25: =COUNTIF($H25:$AL25,AU$5) -> 0 | ... AW25: =COUNTIF($H25:$AL25,AW$5) -> 0

Sheet June
I2: Monthly Leave Tracker
F3: June | G3: 2023 | H3: =IFERROR(VLOOKUP(H4,Holidays,2,0),"") | I3: =IFERROR(VLOOKUP(I4,Holidays,2,0),"") | J3: =IFERROR(VLOOKUP(J4,Holidays,2,0),"") | K3: =IFERROR(VLOOKUP(K4,Holidays,2,0),"") | L3: =IFERROR(VLOOKUP(L4,Holidays,2,0),"") | M3: =IFERROR(VLOOKUP(M4,Holidays,2,0),"") | N3: =IFERROR(VLOOKUP(N4,Holidays,2,0),"") | O3: =IFERROR(VLOOKUP(O4,Holidays,2,0),"") | ... AL3: =IFERROR(VLOOKUP(AL4,Holidays,2,0),"") | AM3: Summary
D4: SL. No. | E4: Emp. Code | F4: Employee Name | G4: Designation | H4: =DATEVALUE("1"&F3&G3) -> 45078 | I4: =IF(H$4<EOMONTH($H$4,0),H4+1,"EOM") -> 45079 | J4: =IF(I$4<EOMONTH($H$4,0),I4+1,"EOM") -> 45080 | K4: =IF(J$4<EOMONTH($H$4,0),J4+1,"EOM") -> 45081 | L4: =IF(K$4<EOMONTH($H$4,0),K4+1,"EOM") -> 45082 | M4: =IF(L$4<EOMONTH($H$4,0),L4+1,"EOM") -> 45083 | N4: =IF(M$4<EOMONTH($H$4,0),M4+1,"EOM") -> 45084 | O4: =IF(N$4<EOMONTH($H$4,0),N4+1,"EOM") -> 45085 | P4: =IF(O$4<EOMONTH($H$4,0),O4+1,"EOM") -> 45086 | ... AL4: =IF(AK$4<EOMONTH($H$4,0),AK4+1,"EOM") -> EOM | AM4: Total Leaves | AN4: Casual Leave | AO4: Privilaged Leave | AP4: Sick Leave | AQ4: Maternity or Paternity | AR4: Half Day | AS4: Work from Home | AT4: Holidays | AU4: Week Offs | AV4: Total Absent / No Show | AW4: Leave Without Pay
H5: =TEXT(H4,"DDD") -> Thu | I5: =TEXT(I4,"DDD") -> Fri | J5: =TEXT(J4,"DDD") -> Sat | K5: =TEXT(K4,"DDD") -> Sun | L5: =TEXT(L4,"DDD") -> Mon | M5: =TEXT(M4,"DDD") -> Tue | N5: =TEXT(N4,"DDD") -> Wed | O5: =TEXT(O4,"DDD") -> Thu | ... AL5: =TEXT(AL4,"DDD") -> EOM | AN5: CL | AO5: PL | AP5: SL | AQ5: ML | AR5: HD | AS5: WH | AT5: H | AU5: WO | AV5: A | AW5: LWP
D6: 1 | E6: =Setting!E4 | F6: =IFERROR(VLOOKUP(E6,Setting!$E:$G,2,0),"") | G6: =IFERROR(VLOOKUP(E6,Setting!$E:$G,3,0),"") | AM6: =SUM(AN6:AW6) -> 0 | AN6: =COUNTIF($H6:$AL6,AN$5) -> 0 | AO6: =COUNTIF($H6:$AL6,AO$5) -> 0 | AP6: =COUNTIF($H6:$AL6,AP$5) -> 0 | AQ6: =COUNTIF($H6:$AL6,AQ$5) -> 0 | AR6: =COUNTIF($H6:$AL6,AR$5) -> 0 | AS6: =COUNTIF($H6:$AL6,AS$5) -> 0 | AT6: =COUNTIF($H6:$AL6,AT$5) -> 0 | AU6: =COUNTIF($H6:$AL6,AU$5) -> 0 | ... AW6: =COUNTIF($H6:$AL6,AW$5) -> 0
D7: 2 | E7: =Setting!E5 | F7: =IFERROR(VLOOKUP(E7,Setting!$E:$G,2,0),"") | G7: =IFERROR(VLOOKUP(E7,Setting!$E:$G,3,0),"") | AM7: =SUM(AN7:AW7) -> 0 | AN7: =COUNTIF($H7:$AL7,AN$5) -> 0 | AO7: =COUNTIF($H7:$AL7,AO$5) -> 0 | AP7: =COUNTIF($H7:$AL7,AP$5) -> 0 | AQ7: =COUNTIF($H7:$AL7,AQ$5) -> 0 | AR7: =COUNTIF($H7:$AL7,AR$5) -> 0 | AS7: =COUNTIF($H7:$AL7,AS$5) -> 0 | AT7: =COUNTIF($H7:$AL7,AT$5) -> 0 | AU7: =COUNTIF($H7:$AL7,AU$5) -> 0 | ... AW7: =COUNTIF($H7:$AL7,AW$5) -> 0
D8: 3 | E8: =Setting!E6 | F8: =IFERROR(VLOOKUP(E8,Setting!$E:$G,2,0),"") | G8: =IFERROR(VLOOKUP(E8,Setting!$E:$G,3,0),"") | AM8: =SUM(AN8:AW8) -> 0 | AN8: =COUNTIF($H8:$AL8,AN$5) -> 0 | AO8: =COUNTIF($H8:$AL8,AO$5) -> 0 | AP8: =COUNTIF($H8:$AL8,AP$5) -> 0 | AQ8: =COUNTIF($H8:$AL8,AQ$5) -> 0 | AR8: =COUNTIF($H8:$AL8,AR$5) -> 0 | AS8: =COUNTIF($H8:$AL8,AS$5) -> 0 | AT8: =COUNTIF($H8:$AL8,AT$5) -> 0 | AU8: =COUNTIF($H8:$AL8,AU$5) -> 0 | ... AW8: =COUNTIF($H8:$AL8,AW$5) -> 0
D9: 4 | E9: =Setting!E7 | F9: =IFERROR(VLOOKUP(E9,Setting!$E:$G,2,0),"") | G9: =IFERROR(VLOOKUP(E9,Setting!$E:$G,3,0),"") | AM9: =SUM(AN9:AW9) -> 0 | AN9: =COUNTIF($H9:$AL9,AN$5) -> 0 | AO9: =COUNTIF($H9:$AL9,AO$5) -> 0 | AP9: =COUNTIF($H9:$AL9,AP$5) -> 0 | AQ9: =COUNTIF($H9:$AL9,AQ$5) -> 0 | AR9: =COUNTIF($H9:$AL9,AR$5) -> 0 | AS9: =COUNTIF($H9:$AL9,AS$5) -> 0 | AT9: =COUNTIF($H9:$AL9,AT$5) -> 0 | AU9: =COUNTIF($H9:$AL9,AU$5) -> 0 | ... AW9: =COUNTIF($H9:$AL9,AW$5) -> 0
D10: 5 | E10: =Setting!E8 | F10: =IFERROR(VLOOKUP(E10,Setting!$E:$G,2,0),"") | G10: =IFERROR(VLOOKUP(E10,Setting!$E:$G,3,0),"") | AM10: =SUM(AN10:AW10) -> 0 | AN10: =COUNTIF($H10:$AL10,AN$5) -> 0 | AO10: =COUNTIF($H10:$AL10,AO$5) -> 0 | AP10: =COUNTIF($H10:$AL10,AP$5) -> 0 | AQ10: =COUNTIF($H10:$AL10,AQ$5) -> 0 | AR10: =COUNTIF($H10:$AL10,AR$5) -> 0 | AS10: =COUNTIF($H10:$AL10,AS$5) -> 0 | AT10: =COUNTIF($H10:$AL10,AT$5) -> 0 | AU10: =COUNTIF($H10:$AL10,AU$5) -> 0 | ... AW10: =COUNTIF($H10:$AL10,AW$5) -> 0
D11: 6 | E11: =Setting!E9 | F11: =IFERROR(VLOOKUP(E11,Setting!$E:$G,2,0),"") | G11: =IFERROR(VLOOKUP(E11,Setting!$E:$G,3,0),"") | AM11: =SUM(AN11:AW11) -> 0 | AN11: =COUNTIF($H11:$AL11,AN$5) -> 0 | AO11: =COUNTIF($H11:$AL11,AO$5) -> 0 | AP11: =COUNTIF($H11:$AL11,AP$5) -> 0 | AQ11: =COUNTIF($H11:$AL11,AQ$5) -> 0 | AR11: =COUNTIF($H11:$AL11,AR$5) -> 0 | AS11: =COUNTIF($H11:$AL11,AS$5) -> 0 | AT11: =COUNTIF($H11:$AL11,AT$5) -> 0 | AU11: =COUNTIF($H11:$AL11,AU$5) -> 0 | ... AW11: =COUNTIF($H11:$AL11,AW$5) -> 0
D12: 7 | E12: =Setting!E10 | F12: =IFERROR(VLOOKUP(E12,Setting!$E:$G,2,0),"") | G12: =IFERROR(VLOOKUP(E12,Setting!$E:$G,3,0),"") | AM12: =SUM(AN12:AW12) -> 0 | AN12: =COUNTIF($H12:$AL12,AN$5) -> 0 | AO12: =COUNTIF($H12:$AL12,AO$5) -> 0 | AP12: =COUNTIF($H12:$AL12,AP$5) -> 0 | AQ12: =COUNTIF($H12:$AL12,AQ$5) -> 0 | AR12: =COUNTIF($H12:$AL12,AR$5) -> 0 | AS12: =COUNTIF($H12:$AL12,AS$5) -> 0 | AT12: =COUNTIF($H12:$AL12,AT$5) -> 0 | AU12: =COUNTIF($H12:$AL12,AU$5) -> 0 | ... AW12: =COUNTIF($H12:$AL12,AW$5) -> 0
